Workbook

Sheet 컬럼정하기_필수 속성값 정리
A1: 컬럼정하기
A2: 품명 | B2: Pneumatic Cylinder | C2: AC Geared Motor | D2: Protection Relay
A3: 속성1 | B3: Model-1 | C3: Model-1 | D3: Model-1
A4: 속성2 | B4: Maker Name-1 | C4: Maker Name-1 | D4: Maker Name-1
A5: 속성3 | B5: Bore Size | C5: Insulation Class | D5: Coil Voltage
A6: 속성4 | B6: Rod Diameter | C6: IP Class | D6: Setting Tap Range
A7: 속성5 | B7: Stroke Length | C7: Number of Poles | D7: Setting Time Range
A8: 속성6 | B8: Pressure Rating | C8: Capacity
A9: 속성7 | C9: Voltage
A10: 속성8 | C10: Frequency
A11: 속성9 | C11: Speed Rating
A12: 속성10 | C12: Speed Reduction Ratio

Sheet Q코드, pdf 파일명 50코드
A1: Q-Code | B1: 그룹사명 | C1: 품명 | D1: Model-1 첨부파일명
A2: Q4675156 | B2: 포스코 | C2: Pneumatic Cylinder | D2: _SMC_CDJ2F16-25Z-A93L-B_CATALOG_20250526104947035.pdf
A3: Q4675089 | B3: 포스코 | C3: Pneumatic Cylinder | D3: _SMC_CDM2B25-25Z-A93L_CATALOG_20250526104540071.pdf
A4: Q4675326 | B4: 포스코 | C4: Pneumatic Cylinder | D4: _SMC_CDQSD16-25DM-A93L_CATALOG_20250528132218077.pdf
A5: Q4675164 | B5: 포스코 | C5: Pneumatic Cylinder | D5: _SMC_CDUK25-30D-A93L_CATALOG_20250526111558421.pdf
A6: Q4683457 | B6: 포스코 | C6: Pneumatic Cylinder | D6: 250812_A2_제선설비부_물품등록자료_T1663035 2FINEX RTO Pneumatic Cylinder CA2B100-300Z Catalog_20250812185026609.pdf
A7: Q4501288 | B7: 포스코 | C7: Pneumatic Cylinder | D7: CS1CN160-100-CJAD0046(업그레이드 품)[1CGL 5.6.7 TB]_20220114112323273.pdf
A8: Q4550786 | B8: 포스코 | C8: Pneumatic Cylinder | D8: ACM_20220111135135572.pdf
A9: Q4549165 | B9: 포스코 | C9: Pneumatic Cylinder | D9: ACM카달로그_20220119165138547.pdf
A10: Q4655802 | B10: 포스코 | C10: Pneumatic Cylinder | D10: Pneumatic cylinder CDA2T80-KRT09KO-200Z-A54L3 SMC_20241112142525736.pdf
A11: Q4627759 | B11: 포스코 | C11: Pneumatic Cylinder | D11: CA2Y 카다로그_20240122135108312.pdf
A12: Q4669390 | B12: 포스코 | C12: Pneumatic Cylinder | D12: CDS1CN125-KRD0368-350-A54L 도면_20250325141804318.pdf
... A73: Q3507398 | B73: 포스코퓨처엠 | C73: Protection Relay | D73: A시리즈 개별 카다로그 (1)_20250210132526349.pdf

Sheet 시스템 읽어올 값.
A1: Q-Code | B1: 그룹사명 | C1: 품명 | D1: Model-1 | E1: Maker Name-1 | F1: Bore Size | G1: Rod Diameter | H1: Stroke Length | I1: Pressure Rating | J1: 정답여부 | K1: Model-1 첨부URL1
A2: Q4675156 | B2: 포스코 | C2: Pneumatic Cylinder | D2: =VLOOKUP(A2,'실린더 상세사양값. 80'!$A$1:$AP$81,40,0) -> CDJ2F16-25Z-A93L-B | E2: =VLOOKUP(A2,'실린더 상세사양값. 80'!$A$1:$BT$81,42,0) -> SMC | F2: =VLOOKUP(A2,'실린더 상세사양값. 80'!$A$1:$CG$81,32,0) -> 16 | G2: =VLOOKUP(A2,'실린더 상세사양값. 80'!$A$1:$CG$81,34,0) -> 16 | H2: =VLOOKUP(A2,'실린더 상세사양값. 80'!$A$1:$CG$81,36,0) -> 25 | I2: =VLOOKUP(A2,'실린더 상세사양값. 80'!$A$1:$CG$81,38,0) -> 7 | J2: 정답 | K2: https://www.smckorea.co.kr/
A3: Q4675089 | B3: 포스코 | C3: Pneumatic Cylinder | D3: =VLOOKUP(A3,'실린더 상세사양값. 80'!$A$1:$AP$81,40,0) -> CDM2B25-25Z-A93L | E3: =VLOOKUP(A3,'실린더 상세사양값. 80'!$A$1:$BT$81,42,0) -> SMC | F3: =VLOOKUP(A3,'실린더 상세사양값. 80'!$A$1:$CG$81,32,0) -> 25 | G3: =VLOOKUP(A3,'실린더 상세사양값. 80'!$A$1:$CG$81,36,0) -> 25 | H3: =VLOOKUP(A3,'실린더 상세사양값. 80'!$A$1:$CG$81,36,0) -> 25 | I3: =VLOOKUP(A3,'실린더 상세사양값. 80'!$A$1:$CG$81,38,0) -> 10 | J3: 정답 | K3: https://www.smckorea.co.kr/
A4: Q4675326 | B4: 포스코 | C4: Pneumatic Cylinder | D4: =VLOOKUP(A4,'실린더 상세사양값. 80'!$A$1:$AP$81,40,0) -> CDQSD16-25DM-A93L | E4: =VLOOKUP(A4,'실린더 상세사양값. 80'!$A$1:$BT$81,42,0) -> SMC | F4: =VLOOKUP(A4,'실린더 상세사양값. 80'!$A$1:$CG$81,32,0) -> 16 | G4: =VLOOKUP(A4,'실린더 상세사양값. 80'!$A$1:$CG$81,36,0) -> 25 | H4: =VLOOKUP(A4,'실린더 상세사양값. 80'!$A$1:$CG$81,36,0) -> 25 | I4: =VLOOKUP(A4,'실린더 상세사양값. 80'!$A$1:$CG$81,38,0) -> 10 | J4: 정답 | K4: https://www.smckorea.co.kr/
A5: Q4675164 | B5: 포스코 | C5: Pneumatic Cylinder | D5: =VLOOKUP(A5,'실린더 상세사양값. 80'!$A$1:$AP$81,40,0) -> CDUK25-30D-A93L | E5: =VLOOKUP(A5,'실린더 상세사양값. 80'!$A$1:$BT$81,42,0) -> SMC | F5: =VLOOKUP(A5,'실린더 상세사양값. 80'!$A$1:$CG$81,32,0) -> 25 | G5: =VLOOKUP(A5,'실린더 상세사양값. 80'!$A$1:$CG$81,36,0) -> 30 | H5: =VLOOKUP(A5,'실린더 상세사양값. 80'!$A$1:$CG$81,36,0) -> 30 | I5: =VLOOKUP(A5,'실린더 상세사양값. 80'!$A$1:$CG$81,38,0) -> 7 | J5: 정답 | K5: https://www.smckorea.co.kr/
A6: Q4683457 | B6: 포스코 | C6: Pneumatic Cylinder | D6: =VLOOKUP(A6,'실린더 상세사양값. 80'!$A$1:$AP$81,40,0) -> CA2B100-300Z | E6: =VLOOKUP(A6,'실린더 상세사양값. 80'!$A$1:$BT$81,42,0) -> SMC | F6: =VLOOKUP(A6,'실린더 상세사양값. 80'!$A$1:$CG$81,32,0) -> 100 | G6: =VLOOKUP(A6,'실린더 상세사양값. 80'!$A$1:$CG$81,36,0) -> 300 | H6: =VLOOKUP(A6,'실린더 상세사양값. 80'!$A$1:$CG$81,36,0) -> 300 | I6: =VLOOKUP(A6,'실린더 상세사양값. 80'!$A$1:$CG$81,38,0) -> 10 | J6: 정답 | K6: https://www.smcpneumatics.com/CA2B100-300Z.html
A7: Q4501288 | B7: 포스코 | C7: Pneumatic Cylinder | D7: =VLOOKUP(A7,'실린더 상세사양값. 80'!$A$1:$AP$81,40,0) -> CS1CN160-100-CJAD0046 | E7: =VLOOKUP(A7,'실린더 상세사양값. 80'!$A$1:$BT$81,42,0) -> SMC | F7: =VLOOKUP(A7,'실린더 상세사양값. 80'!$A$1:$CG$81,32,0) -> 160 | G7: =VLOOKUP(A7,'실린더 상세사양값. 80'!$A$1:$CG$81,36,0) -> 100 | H7: =VLOOKUP(A7,'실린더 상세사양값. 80'!$A$1:$CG$81,36,0) -> 100 | I7: =VLOOKUP(A7,'실린더 상세사양값. 80'!$A$1:$CG$81,38,0) -> 0 | J7: 정답 | K7: http://www.smcpneumatics.com/pdfs/smc/70ACS1.pdf
A8: Q4550786 | B8: 포스코 | C8: Pneumatic Cylinder | D8: =VLOOKUP(A8,'실린더 상세사양값. 80'!$A$1:$AP$81,40,0) -> ACM-N-FA50-S425 | E8: =VLOOKUP(A8,'실린더 상세사양값. 80'!$A$1:$BT$81,42,0) -> KCC | F8: =VLOOKUP(A8,'실린더 상세사양값. 80'!$A$1:$CG$81,32,0) -> 50 | G8: =VLOOKUP(A8,'실린더 상세사양값. 80'!$A$1:$CG$81,36,0) -> 425 | H8: =VLOOKUP(A8,'실린더 상세사양값. 80'!$A$1:$CG$81,36,0) -> 425 | I8: =VLOOKUP(A8,'실린더 상세사양값. 80'!$A$1:$CG$81,38,0) -> 10 | J8: 정답 | K8: https://www.kccpr.com/bbs/search.php?url=https%3A%2F%2Fwww.kccpr.com%2Fbbs%2Fsearch.php&stx=ACM
A9: Q4549165 | B9: 포스코 | C9: Pneumatic Cylinder | D9: =VLOOKUP(A9,'실린더 상세사양값. 80'!$A$1:$AP$81,40,0) -> ACM-N-TC80-S125-J | E9: =VLOOKUP(A9,'실린더 상세사양값. 80'!$A$1:$BT$81,42,0) -> KCC | F9: =VLOOKUP(A9,'실린더 상세사양값. 80'!$A$1:$CG$81,32,0) -> 80 | G9: =VLOOKUP(A9,'실린더 상세사양값. 80'!$A$1:$CG$81,36,0) -> 125 | H9: =VLOOKUP(A9,'실린더 상세사양값. 80'!$A$1:$CG$81,36,0) -> 125 | I9: =VLOOKUP(A9,'실린더 상세사양값. 80'!$A$1:$CG$81,38,0) -> 10 | J9: 정답 | K9: https://www.kccpr.com/bbs/search.php?url=https%3A%2F%2Fwww.kccpr.com%2Fbbs%2Fsearch.php&stx=ACM
A10: Q4655802 | B10: 포스코 | C10: Pneumatic Cylinder | D10: =VLOOKUP(A10,'실린더 상세사양값. 80'!$A$1:$AP$81,40,0) -> CDA2T80-KRT09KO-200Z-A54L3 | E10: =VLOOKUP(A10,'실린더 상세사양값. 80'!$A$1:$BT$81,42,0) -> SMC | F10: =VLOOKUP(A10,'실린더 상세사양값. 80'!$A$1:$CG$81,32,0) -> 80 | G10: =VLOOKUP(A10,'실린더 상세사양값. 80'!$A$1:$CG$81,36,0) -> 200 | H10: =VLOOKUP(A10,'실린더 상세사양값. 80'!$A$1:$CG$81,36,0) -> 200 | I10: =VLOOKUP(A10,'실린더 상세사양값. 80'!$A$1:$CG$81,38,0) -> 10 | J10: 정답 | K10: https://www.smckorea.co.kr/ppis/data/catalog/CA2-Z.pdf
A11: Q4627759 | B11: 포스코 | C11: Pneumatic Cylinder | D11: =VLOOKUP(A11,'실린더 상세사양값. 80'!$A$1:$AP$81,40,0) -> CA2YT80-150Z-W | E11: =VLOOKUP(A11,'실린더 상세사양값. 80'!$A$1:$BT$81,42,0) -> SMC | F11: =VLOOKUP(A11,'실린더 상세사양값. 80'!$A$1:$CG$81,32,0) -> 80 | G11: =VLOOKUP(A11,'실린더 상세사양값. 80'!$A$1:$CG$81,36,0) -> 150 | H11: =VLOOKUP(A11,'실린더 상세사양값. 80'!$A$1:$CG$81,36,0) -> 150 | I11: =VLOOKUP(A11,'실린더 상세사양값. 80'!$A$1:$CG$81,38,0) -> 0 | J11: 정답
A12: Q4669390 | B12: 포스코 | C12: Pneumatic Cylinder | D12: =VLOOKUP(A12,'실린더 상세사양값. 80'!$A$1:$AP$81,40,0) -> CDS1CN125-KRD0368-350-A54L | E12: =VLOOKUP(A12,'실린더 상세사양값. 80'!$A$1:$BT$81,42,0) -> SMC | F12: =VLOOKUP(A12,'실린더 상세사양값. 80'!$A$1:$CG$81,32,0) -> 125 | G12: =VLOOKUP(A12,'실린더 상세사양값. 80'!$A$1:$CG$81,36,0) -> 350 | H12: =VLOOKUP(A12,'실린더 상세사양값. 80'!$A$1:$CG$81,36,0) -> 350 | I12: =VLOOKUP(A12,'실린더 상세사양값. 80'!$A$1:$CG$81,38,0) -> 15 | J12: 정답 | K12: https://www.smckorea.co.kr/ppis/data/catalog/CS1.pdf
A13: Q4629827 | B13: 포스코 | C13: Pneumatic Cylinder | D13: =VLOOKUP(A13,'실린더 상세사양값. 80'!$A$1:$AP$81,40,0) -> CDS1TN125-KRD0368-500-Z73L | E13: =VLOOKUP(A13,'실린더 상세사양값. 80'!$A$1:$BT$81,42,0) -> SMC | F13: =VLOOKUP(A13,'실린더 상세사양값. 80'!$A$1:$CG$81,32,0) -> 125 | G13: =VLOOKUP(A13,'실린더 상세사양값. 80'!$A$1:$CG$81,36,0) -> 500 | H13: =VLOOKUP(A13,'실린더 상세사양값. 80'!$A$1:$CG$81,36,0) -> 500 | I13: =VLOOKUP(A13,'실린더 상세사양값. 80'!$A$1:$CG$81,38,0) -> 9.7 | J13: 정답
A14: Q4627207 | B14: 포스코 | C14: Pneumatic Cylinder | D14: =VLOOKUP(A14,'실린더 상세사양값. 80'!$A$1:$AP$81,40,0) -> CDS2T200-200-CJCD0039 | E14: =VLOOKUP(A14,'실린더 상세사양값. 80'!$A$1:$BT$81,42,0) -> SMC | F14: =VLOOKUP(A14,'실린더 상세사양값. 80'!$A$1:$CG$81,32,0) -> 200 | G14: =VLOOKUP(A14,'실린더 상세사양값. 80'!$A$1:$CG$81,36,0) -> 220 | H14: =VLOOKUP(A14,'실린더 상세사양값. 80'!$A$1:$CG$81,36,0) -> 220 | I14: =VLOOKUP(A14,'실린더 상세사양값. 80'!$A$1:$CG$81,38,0) -> 16 | J14: 정답
A15: Q4636670 | B15: 포스코 | C15: Pneumatic Cylinder | D15: =VLOOKUP(A15,'실린더 상세사양값. 80'!$A$1:$AP$81,40,0) -> CDS2T320-250-CJCD0239 | E15: =VLOOKUP(A15,'실린더 상세사양값. 80'!$A$1:$BT$81,42,0) -> SMC | F15: =VLOOKUP(A15,'실린더 상세사양값. 80'!$A$1:$CG$81,32,0) -> 320 | G15: =VLOOKUP(A15,'실린더 상세사양값. 80'!$A$1:$CG$81,36,0) -> 250 | H15: =VLOOKUP(A15,'실린더 상세사양값. 80'!$A$1:$CG$81,36,0) -> 250 | I15: =VLOOKUP(A15,'실린더 상세사양값. 80'!$A$1:$CG$81,38,0) -> 0 | J15: 정답
A16: Q4680486 | B16: 포스코 | C16: Pneumatic Cylinder | D16: =VLOOKUP(A16,'실린더 상세사양값. 80'!$A$1:$AP$81,40,0) -> CG1DN63-64-CJD00567 | E16: =VLOOKUP(A16,'실린더 상세사양값. 80'!$A$1:$BT$81,42,0) -> SMC | F16: =VLOOKUP(A16,'실린더 상세사양값. 80'!$A$1:$CG$81,32,0) -> 63 | G16: =VLOOKUP(A16,'실린더 상세사양값. 80'!$A$1:$CG$81,36,0) -> 64 | H16: =VLOOKUP(A16,'실린더 상세사양값. 80'!$A$1:$CG$81,36,0) -> 64 | I16: =VLOOKUP(A16,'실린더 상세사양값. 80'!$A$1:$CG$81,38,0) -> 10 | J16: 정답 | K16: https://www.smckorea.co.kr/ppis/data/domyun/CJD00567-AP..pdf
A17: Q4697437 | B17: 포스코 | C17: Pneumatic Cylinder | D17: =VLOOKUP(A17,'실린더 상세사양값. 80'!$A$1:$AP$81,40,0) -> CDS1TN200-246K-A54 | E17: =VLOOKUP(A17,'실린더 상세사양값. 80'!$A$1:$BT$81,42,0) -> SMC | F17: =VLOOKUP(A17,'실린더 상세사양값. 80'!$A$1:$CG$81,32,0) -> 200 | G17: =VLOOKUP(A17,'실린더 상세사양값. 80'!$A$1:$CG$81,36,0) -> 246 | H17: =VLOOKUP(A17,'실린더 상세사양값. 80'!$A$1:$CG$81,36,0) -> 246 | I17: =VLOOKUP(A17,'실린더 상세사양값. 80'!$A$1:$CG$81,38,0) -> 9999 | J17: 정답
A18: Q4371330 | B18: 포스코 | C18: Pneumatic Cylinder | D18: =VLOOKUP(A18,'실린더 상세사양값. 80'!$A$1:$AP$81,40,0) -> CDQ2B50-55Z-DCN446GN | E18: =VLOOKUP(A18,'실린더 상세사양값. 80'!$A$1:$BT$81,42,0) -> SMC | F18: =VLOOKUP(A18,'실린더 상세사양값. 80'!$A$1:$CG$81,32,0) -> 50 | G18: =VLOOKUP(A18,'실린더 상세사양값. 80'!$A$1:$CG$81,36,0) -> 9999 | H18: =VLOOKUP(A18,'실린더 상세사양값. 80'!$A$1:$CG$81,36,0) -> 9999 | I18: =VLOOKUP(A18,'실린더 상세사양값. 80'!$A$1:$CG$81,38,0) -> 10 | J18: 정답 | K18: http://www.smckorea.co.kr/esales/data/sangpum/catalog/CQ2-Z.pdf
A19: Q4037566 | B19: 포스코 | C19: Pneumatic Cylinder | D19: =VLOOKUP(A19,'실린더 상세사양값. 80'!$A$1:$AP$81,40,0) -> CDS1TN140-KRT04KO-710-XC14 +D-A54Z(2EA)+BT-12(2EA) | E19: =VLOOKUP(A19,'실린더 상세사양값. 80'!$A$1:$BT$81,42,0) -> SMC | F19: =VLOOKUP(A19,'실린더 상세사양값. 80'!$A$1:$CG$81,32,0) -> 140 | G19: =VLOOKUP(A19,'실린더 상세사양값. 80'!$A$1:$CG$81,36,0) -> 710 | H19: =VLOOKUP(A19,'실린더 상세사양값. 80'!$A$1:$CG$81,36,0) -> 710 | I19: =VLOOKUP(A19,'실린더 상세사양값. 80'!$A$1:$CG$81,38,0) -> 10 | J19: 정답 | K19: http://www.smckorea.co.kr/homepage/ver3.5/product/catalogue_sub_detail.asp?no=914#
A20: Q4521203 | B20: 포스코 | C20: Pneumatic Cylinder | D20: =VLOOKUP(A20,'실린더 상세사양값. 80'!$A$1:$AP$81,40,0) -> C96SD100-320C | E20: =VLOOKUP(A20,'실린더 상세사양값. 80'!$A$1:$BT$81,42,0) -> SMC | F20: =VLOOKUP(A20,'실린더 상세사양값. 80'!$A$1:$CG$81,32,0) -> 100 | G20: =VLOOKUP(A20,'실린더 상세사양값. 80'!$A$1:$CG$81,36,0) -> 320 | H20: =VLOOKUP(A20,'실린더 상세사양값. 80'!$A$1:$CG$81,36,0) -> 320 | I20: =VLOOKUP(A20,'실린더 상세사양값. 80'!$A$1:$CG$81,38,0) -> 10 | J20: 정답 | K20: http://www.smckorea.co.kr/ppis/data/catalog/C96.pdf
A21: Q4511190 | B21: 포스코 | C21: Pneumatic Cylinder | D21: =VLOOKUP(A21,'실린더 상세사양값. 80'!$A$1:$AP$81,40,0) -> CDA2T100-KRT09KO-125Z-W-A96L | E21: =VLOOKUP(A21,'실린더 상세사양값. 80'!$A$1:$BT$81,42,0) -> SMC | F21: =VLOOKUP(A21,'실린더 상세사양값. 80'!$A$1:$CG$81,32,0) -> 100 | G21: =VLOOKUP(A21,'실린더 상세사양값. 80'!$A$1:$CG$81,36,0) -> 125 | H21: =VLOOKUP(A21,'실린더 상세사양값. 80'!$A$1:$CG$81,36,0) -> 125 | I21: =VLOOKUP(A21,'실린더 상세사양값. 80'!$A$1:$CG$81,38,0) -> 0 | J21: 정답 | K21: http://www.smckorea.co.kr/ppis/data/catalog/CA2-Z.pdf
A22: Q4520279 | B22: 포스코 | C22: Pneumatic Cylinder | D22: =VLOOKUP(A22,'실린더 상세사양값. 80'!$A$1:$AP$81,40,0) -> CDG1UN50TF-170-CJZH0846 | E22: =VLOOKUP(A22,'실린더 상세사양값. 80'!$A$1:$BT$81,42,0) -> SMC | F22: =VLOOKUP(A22,'실린더 상세사양값. 80'!$A$1:$CG$81,32,0) -> 50 | G22: =VLOOKUP(A22,'실린더 상세사양값. 80'!$A$1:$CG$81,36,0) -> 170 | H22: =VLOOKUP(A22,'실린더 상세사양값. 80'!$A$1:$CG$81,36,0) -> 170 | I22: =VLOOKUP(A22,'실린더 상세사양값. 80'!$A$1:$CG$81,38,0) -> 10 | J22: 정답 | K22: http://www.smckorea.co.kr/ppis/data/catalog/CG1-Z.pdf
A23: Q4508586 | B23: 포스코 | C23: Pneumatic Cylinder | D23: =VLOOKUP(A23,'실린더 상세사양값. 80'!$A$1:$AP$81,40,0) -> CDM2E32-200Z-NW-A93L | E23: =VLOOKUP(A23,'실린더 상세사양값. 80'!$A$1:$BT$81,42,0) -> SMC | F23: =VLOOKUP(A23,'실린더 상세사양값. 80'!$A$1:$CG$81,32,0) -> 9999 | G23: =VLOOKUP(A23,'실린더 상세사양값. 80'!$A$1:$CG$81,36,0) -> 9999 | H23: =VLOOKUP(A23,'실린더 상세사양값. 80'!$A$1:$CG$81,36,0) -> 9999 | I23: =VLOOKUP(A23,'실린더 상세사양값. 80'!$A$1:$CG$81,38,0) -> 0 | J23: 정답 | K23: http://www.smckorea.co.kr/ppis/data/catalog/CM2-Z.pdf
A24: Q4520278 | B24: 포스코 | C24: Pneumatic Cylinder | D24: =VLOOKUP(A24,'실린더 상세사양값. 80'!$A$1:$AP$81,40,0) -> CDM2E40TF-160Z-XC6 | E24: =VLOOKUP(A24,'실린더 상세사양값. 80'!$A$1:$BT$81,42,0) -> SMC | F24: =VLOOKUP(A24,'실린더 상세사양값. 80'!$A$1:$CG$81,32,0) -> 40 | G24: =VLOOKUP(A24,'실린더 상세사양값. 80'!$A$1:$CG$81,36,0) -> 160 | H24: =VLOOKUP(A24,'실린더 상세사양값. 80'!$A$1:$CG$81,36,0) -> 160 | I24: =VLOOKUP(A24,'실린더 상세사양값. 80'!$A$1:$CG$81,38,0) -> 10 | J24: 정답 | K24: http://www.smckorea.co.kr/ppis/data/catalog/CM2-Z.pdf
A25: Q4507377 | B25: 포스코 | C25: Pneumatic Cylinder | D25: =VLOOKUP(A25,'실린더 상세사양값. 80'!$A$1:$AP$81,40,0) -> CDQMB50-10-A72 | E25: =VLOOKUP(A25,'실린더 상세사양값. 80'!$A$1:$BT$81,42,0) -> SMC | F25: =VLOOKUP(A25,'실린더 상세사양값. 80'!$A$1:$CG$81,32,0) -> 50 | G25: =VLOOKUP(A25,'실린더 상세사양값. 80'!$A$1:$CG$81,36,0) -> 10 | H25: =VLOOKUP(A25,'실린더 상세사양값. 80'!$A$1:$CG$81,36,0) -> 10 | I25: =VLOOKUP(A25,'실린더 상세사양값. 80'!$A$1:$CG$81,38,0) -> 10 | J25: 정답 | K25: http://www.smckorea.co.kr/ppis/data/catalog/CQM.pdf
A26: Q3507377 | B26: 포스코 | C26: Pneumatic Cylinder | D26: CDS2T3200-250-CJCD0239 | E26: SMC | F26: 50 | G26: 10 | H26: 10 | I26: 10 | J26: 오류치 | K26: https://www.smckorea.co.kr/ppis/data/catalog/CA2-Z.pdf
A27: Q3507378 | B27: 포스코 | C27: Pneumatic Cylinder | D27: CPS2T3200-250-CJCD0235 | E27: SMC | F27: 51 | G27: 11 | H27: 12 | I27: 19 | J27: 오류치 | K27: https://www.smckorea.co.kr/ppis/data/catalog/CA2-Z.pdf
A28: Q3507379 | B28: 포스코 | C28: Pneumatic Cylinder | D28: CDS2T3200-250-CJCD0240 | E28: SMC | F28: 50 | G28: 32 | H28: 10 | I28: 11 | J28: 오류치 | K28: https://www.smckorea.co.kr/ppis/data/catalog/CA2-Z.pdf
A29: Q3507380 | B29: 포스코 | C29: Pneumatic Cylinder | D29: CPS2T3200-250-CJCD0236 | E29: SMC | F29: 51 | G29: 35 | H29: 7 | I29: 12 | J29: 오류치 | K29: https://www.smckorea.co.kr/ppis/data/catalog/CA2-Z.pdf
A30: Q3507381 | B30: 포스코 | C30: Pneumatic Cylinder | D30: CDS2T3200-250-CJCD0241 | E30: SMC | F30: 50 | G30: 10 | H30: 10 | I30: 14 | J30: 오류치 | K30: https://www.smckorea.co.kr/ppis/data/catalog/CA2-Z.pdf
A31: Q3507382 | B31: 포스코 | C31: Pneumatic Cylinder | D31: CPS2T3200-250-CJCD0237 | E31: SMC | F31: 51 | G31: 11 | H31: 42 | I31: 15 | J31: 오류치 | K31: https://www.smckorea.co.kr/ppis/data/catalog/CA2-Z.pdf
A32: Q3507383 | B32: 포스코 | C32: Pneumatic Cylinder | D32: CDS2T3200-250-CJCD0242 | E32: SMC | F32: 50 | G32: 11 | H32: 10 | I32: 123 | J32: 오류치 | K32: https://www.smckorea.co.kr/ppis/data/catalog/CA2-Z.pdf
A35: Q-Code | B35: 그룹사명 | C35: 품명 | D35: Model-1 | E35: Maker Name-1 | F35: Insulation Class | G35: IP Class | H35: Number of Poles | I35: Capacity | J35: Voltage | K35: Frequency | L35: Speed Rating | M35: Speed Reduction Ratio | N35: 정답여부
A36: Q4632857 | B36: 포스코 | C36: AC Geared Motor | D36: =VLOOKUP(A36,'모터 상세사양값'!$A$1:$CG$27,28,0) -> DHHM8-9175-43 | E36: =VLOOKUP(A36,'모터 상세사양값'!$A$1:$CG$27,30,0) -> HANA MECHANICAL&ELECTRICAL | F36: =VLOOKUP(A36,'모터 상세사양값'!$A$1:$CG$27,52,0) -> F | G36: =VLOOKUP(A36,'모터 상세사양값'!$A$1:$CG$27,54,0) -> 0 | H36: =VLOOKUP(A36,'모터 상세사양값'!$A$1:$CG$27,56,0) -> 4 | I36: =VLOOKUP(A36,'모터 상세사양값'!$A$1:$CG$27,58,0) -> 5.5 | J36: =VLOOKUP(A36,'모터 상세사양값'!$A$1:$CG$27,60,0) -> 440 | K36: =VLOOKUP(A36,'모터 상세사양값'!$A$1:$CG$27,62,0) -> 60 | L36: =VLOOKUP(A36,'모터 상세사양값'!$A$1:$CG$27,64,0) -> 1780 | M36: =VLOOKUP(A36,'모터 상세사양값'!$A$1:$CG$27,66,0) -> 1/43 | N36: 정답
A37: Q4636710 | B37: 포스코 | C37: AC Geared Motor | D37: =VLOOKUP(A37,'모터 상세사양값'!$A$1:$CG$27,28,0) -> R47 DRN100L4 | E37: =VLOOKUP(A37,'모터 상세사양값'!$A$1:$CG$27,30,0) -> SEW | F37: =VLOOKUP(A37,'모터 상세사양값'!$A$1:$CG$27,52,0) -> 155F | G37: =VLOOKUP(A37,'모터 상세사양값'!$A$1:$CG$27,54,0) -> IP54 | H37: =VLOOKUP(A37,'모터 상세사양값'!$A$1:$CG$27,56,0) -> 4 | I37: =VLOOKUP(A37,'모터 상세사양값'!$A$1:$CG$27,58,0) -> 2.2 | J37: =VLOOKUP(A37,'모터 상세사양값'!$A$1:$CG$27,60,0) -> 254/440 | K37: =VLOOKUP(A37,'모터 상세사양값'!$A$1:$CG$27,62,0) -> 60 | L37: =VLOOKUP(A37,'모터 상세사양값'!$A$1:$CG$27,64,0) -> 1765/174 | M37: =VLOOKUP(A37,'모터 상세사양값'!$A$1:$CG$27,66,0) -> 1/10.15 | N37: 정답
A38: Q4688576 | B38: 포스코 | C38: AC Geared Motor | D38: =VLOOKUP(A38,'모터 상세사양값'!$A$1:$CG$27,28,0) -> RPH | E38: =VLOOKUP(A38,'모터 상세사양값'!$A$1:$CG$27,30,0) -> HYOSUNG | F38: =VLOOKUP(A38,'모터 상세사양값'!$A$1:$CG$27,52,0) -> F | G38: =VLOOKUP(A38,'모터 상세사양값'!$A$1:$CG$27,54,0) -> IP55 | H38: =VLOOKUP(A38,'모터 상세사양값'!$A$1:$CG$27,56,0) -> 4 | I38: =VLOOKUP(A38,'모터 상세사양값'!$A$1:$CG$27,58,0) -> 0.75 | J38: =VLOOKUP(A38,'모터 상세사양값'!$A$1:$CG$27,60,0) -> 440 | K38: =VLOOKUP(A38,'모터 상세사양값'!$A$1:$CG$27,62,0) -> 60 | L38: =VLOOKUP(A38,'모터 상세사양값'!$A$1:$CG$27,64,0) -> 1735/35 | M38: =VLOOKUP(A38,'모터 상세사양값'!$A$1:$CG$27,66,0) -> 1/50 | N38: 정답
A39: Q4688760 | B39: 포스코 | C39: AC Geared Motor | D39: =VLOOKUP(A39,'모터 상세사양값'!$A$1:$CG$27,28,0) -> RPH | E39: =VLOOKUP(A39,'모터 상세사양값'!$A$1:$CG$27,30,0) -> HYOSUNG | F39: =VLOOKUP(A39,'모터 상세사양값'!$A$1:$CG$27,52,0) -> F | G39: =VLOOKUP(A39,'모터 상세사양값'!$A$1:$CG$27,54,0) -> IP55 | H39: =VLOOKUP(A39,'모터 상세사양값'!$A$1:$CG$27,56,0) -> 4 | I39: =VLOOKUP(A39,'모터 상세사양값'!$A$1:$CG$27,58,0) -> 1.5 | J39: =VLOOKUP(A39,'모터 상세사양값'!$A$1:$CG$27,60,0) -> 440 | K39: =VLOOKUP(A39,'모터 상세사양값'!$A$1:$CG$27,62,0) -> 60 | L39: =VLOOKUP(A39,'모터 상세사양값'!$A$1:$CG$27,64,0) -> 1750/29.2 | M39: =VLOOKUP(A39,'모터 상세사양값'!$A$1:$CG$27,66,0) -> 60 | N39: 정답
A40: Q4622968 | B40: 포스코 | C40: AC Geared Motor | D40: =VLOOKUP(A40,'모터 상세사양값'!$A$1:$CG$27,28,0) -> HLA020101057587 | E40: =VLOOKUP(A40,'모터 상세사양값'!$A$1:$CG$27,30,0) -> HYOSUNG | F40: =VLOOKUP(A40,'모터 상세사양값'!$A$1:$CG$27,52,0) -> F | G40: =VLOOKUP(A40,'모터 상세사양값'!$A$1:$CG$27,54,0) -> TE | H40: =VLOOKUP(A40,'모터 상세사양값'!$A$1:$CG$27,56,0) -> 4 | I40: =VLOOKUP(A40,'모터 상세사양값'!$A$1:$CG$27,58,0) -> 1.5 | J40: =VLOOKUP(A40,'모터 상세사양값'!$A$1:$CG$27,60,0) -> 440 | K40: =VLOOKUP(A40,'모터 상세사양값'!$A$1:$CG$27,62,0) -> 60 | L40: =VLOOKUP(A40,'모터 상세사양값'!$A$1:$CG$27,64,0) -> 1750 | M40: =VLOOKUP(A40,'모터 상세사양값'!$A$1:$CG$27,66,0) -> 1/15 | N40: 정답
A41: Q4621316 | B41: 포스코 | C41: AC Geared Motor | D41: =VLOOKUP(A41,'모터 상세사양값'!$A$1:$CG$27,28,0) -> HMA01080000560 | E41: =VLOOKUP(A41,'모터 상세사양값'!$A$1:$CG$27,30,0) -> HYOSUNG | F41: =VLOOKUP(A41,'모터 상세사양값'!$A$1:$CG$27,52,0) -> F | G41: =VLOOKUP(A41,'모터 상세사양값'!$A$1:$CG$27,54,0) -> TE | H41: =VLOOKUP(A41,'모터 상세사양값'!$A$1:$CG$27,56,0) -> 4 | I41: =VLOOKUP(A41,'모터 상세사양값'!$A$1:$CG$27,58,0) -> 3.7 | J41: =VLOOKUP(A41,'모터 상세사양값'!$A$1:$CG$27,60,0) -> 440 | K41: =VLOOKUP(A41,'모터 상세사양값'!$A$1:$CG$27,62,0) -> 60 | L41: =VLOOKUP(A41,'모터 상세사양값'!$A$1:$CG$27,64,0) -> 1755 | M41: =VLOOKUP(A41,'모터 상세사양값'!$A$1:$CG$27,66,0) -> 1/120 | N41: 정답
A42: Q4621046 | B42: 포스코 | C42: AC Geared Motor | D42: =VLOOKUP(A42,'모터 상세사양값'!$A$1:$CG$27,28,0) -> HLA020101057590 | E42: =VLOOKUP(A42,'모터 상세사양값'!$A$1:$CG$27,30,0) -> HYOSUNG | F42: =VLOOKUP(A42,'모터 상세사양값'!$A$1:$CG$27,52,0) -> F | G42: =VLOOKUP(A42,'모터 상세사양값'!$A$1:$CG$27,54,0) -> TE | H42: =VLOOKUP(A42,'모터 상세사양값'!$A$1:$CG$27,56,0) -> 4 | I42: =VLOOKUP(A42,'모터 상세사양값'!$A$1:$CG$27,58,0) -> 5.5 | J42: =VLOOKUP(A42,'모터 상세사양값'!$A$1:$CG$27,60,0) -> 440 | K42: =VLOOKUP(A42,'모터 상세사양값'!$A$1:$CG$27,62,0) -> 60 | L42: =VLOOKUP(A42,'모터 상세사양값'!$A$1:$CG$27,64,0) -> 1775 | M42: =VLOOKUP(A42,'모터 상세사양값'!$A$1:$CG$27,66,0) -> 1/100 | N42: 정답
...

Sheet 공압실린더 56개 
A1: Q-Code | B1: =COUNTA(B2:B1048576) -> 77 | C1: 그룹사명 | D1: 품명 | E1: Purchase Category | F1: 표준화섹션담당자 | G1: 자재특성구분 | H1: 처리상태 | I1: 조달 | J1: 통화 | K1: 사양 및 규격 | L1: 단위 | M1: 계약형태 | N1: Model-1 | O1: Maker-1 | P1: Option-1 | Q1: Model-2 | R1: Maker-2 | S1: Option-2 | T1: Model-3 | U1: Maker-3 | V1: Option-3 | W1: Option & Others | X1: Application | Y1: 도면번호1 | Z1: 첨부도면파일명 | AA1: 첨부자재규격서명 | AB1: Model-1 첨부파일명 | AC1: Model-2 첨부파일명 | AD1: Model-3 첨부파일명 | AE1: Model-1 첨부URL1 | AF1: Model-1 첨부URL2 | AG1: Model-2 첨부URL1 | AH1: 첨부Image파일명1 | AI1: 첨부Image파일명2 | AJ1: 신청자명 | AK1: 신청자 소속 | AL1: 신청자 E-mail | AM1: 요청자명 | AN1: 요청자 소속 | AO1: 요청자 E-mail | AP1: 최종검토일 | AQ1: 년도 | AR1: 단수승인사유 | AS1: 검토자 메모 | AT1: 월별Inactive대상
A2: Q4675156 | B2: 0 | C2: 포스코 | D2: Pneumatic Cylinder | E2: Pneumatic Cylinder | F2: 전아람 | G2: 특정사양품(단수) | H2: ACTIVE | I2: L | J2: KRW | K2: CWC(DA),16Dx16Dx25ST,7kgf/cm2,[CDJ2F16-25Z-A93L-B/SMC],FOR CHARPY IMPACT TESTER(SETTER),OR EQUIVALENT | L2: EA | M2: STANDARD | N2: CDJ2F16-25Z-A93L-B | O2: SMC | R2: NONE | X2: FOR CHARPY IMPACT TESTER(SETTER) | AB2: _SMC_CDJ2F16-25Z-A93L-B_CATALOG_20250526104947035.pdf | AE2: https://www.smckorea.co.kr/ | AH2: SMC_CDJ2F16-25Z-A93L-B_20250526105245175.jpg | AJ2: 권우석 | AK2: (포항)품질기술부 재질시험섹션 | AL2: kws80395@posco.co.kr | AM2: 박민우 | AN2: (포항)품질기술부 재질시험섹션 | AO2: cinnamon@posco.co.kr | AP2: 2025-05-28 11:05:31 | AQ2: 2025 | AR2: 차후 재점검 | AS2: 기 설치된 물품의 호환성을 위해 특정 사양으로 등록건 확인,_x000D_ Q4644072등 유사item 검색하였으나, 유사/동일품 없음 확인후 승인합니다._x000D_ (특정 사양품감축 관련) 차후 입고시 스케치, 현물 확인을 통한 도면화, 일반 사양화, 복수화 전환 검토 요청 필히 부탁드립니다. 감사합니다._x000D_ | AT2: N
A3: Q4675089 | B3: 0 | C3: 포스코 | D3: Pneumatic Cylinder | E3: Pneumatic Cylinder | F3: 전아람 | G3: 특정사양품(단수) | H3: ACTIVE | I3: L | J3: KRW | K3: CWC(DA),25Dx25Dx25ST,10kgf/cm2,[CDM2B25-25Z-A93L/SMC],FOR CHARPY IMPACT TESTER(STOPPER),OR EQUIVALENT | L3: EA | M3: STANDARD | N3: CDM2B25-25Z-A93L | O3: SMC | R3: NONE | X3: FOR CHARPY IMPACT TESTER(STOPPER) | AB3: _SMC_CDM2B25-25Z-A93L_CATALOG_20250526104540071.pdf | AE3: https://www.smckorea.co.kr/ | AH3: SMC_CDM2B25-25Z-A93L_20250526104504139.jpg | AJ3: 권우석 | AK3: (포항)품질기술부 재질시험섹션 | AL3: kws80395@posco.co.kr | AM3: 박민우 | AN3: (포항)품질기술부 재질시험섹션 | AO3: cinnamon@posco.co.kr | AP3: 2025-05-27 17:05:32 | AQ3: 2025 | AR3: 차후 재점검 | AS3: 기 설치된 물품의 호환성을 위해 특정 사양으로 등록건 확인,_x000D_ Q4290511등 유사item 검색하였으나, 유사/동일품 없음 확인후 승인합니다._x000D_ (특정 사양품감축 관련) 차후 입고시 스케치, 현물 확인을 통한 도면화, 일반 사양화, 복수화 전환 검토 요청 필히 부탁드립니다. 감사합니다._x000D_ | AT3: N
A4: Q4675326 | B4: 0 | C4: 포스코 | D4: Pneumatic Cylinder | E4: Pneumatic Cylinder | F4: 전아람 | G4: 특정사양품(단수) | H4: ACTIVE | I4: L | J4: KRW | K4: CWC(DA),16Dx16Dx25ST,10kgf/cm2,[CDQSD16-25DM-A93L/SMC],FOR CHARPY IMPACT TESTER(HOLDER),OR EQUIVALENT | L4: EA | M4: STANDARD | N4: CDQSD16-25DM-A93L | O4: SMC | R4: NONE | X4: FOR CHARPY IMPACT TESTER(HOLDER) | AB4: _SMC_CDQSD16-25DM-A93L_CATALOG_20250528132218077.pdf | AE4: https://www.smckorea.co.kr/ | AH4: SMC_CDQSD16-25DM-A93L_20250528132218190.jpg | AJ4: 권우석 | AK4: (포항)품질기술부 재질시험섹션 | AL4: kws80395@posco.co.kr | AM4: 박민우 | AN4: (포항)품질기술부 재질시험섹션 | AO4: cinnamon@posco.co.kr | AP4: 2025-05-29 13:05:54 | AQ4: 2025 | AR4: 차후 재점검 | AS4: 기 설치된 물품의 호환성을 위해 특정 사양으로 등록건 확인,_x000D_ Q4644099등 유사item 검색하였으나, 유사/동일품 없음 확인후 승인합니다._x000D_ (특정 사양품감축 관련) 차후 입고시 스케치, 현물 확인을 통한 도면화, 일반 사양화, 복수화 전환 검토 요청 필히 부탁드립니다. 감사합니다._x000D_ _x000D_ | AT4: N
A5: Q4675164 | B5: 0 | C5: 포스코 | D5: Pneumatic Cylinder | E5: Pneumatic Cylinder | F5: 전아람 | G5: 특정사양품(단수) | H5: ACTIVE | I5: L | J5: KRW | K5: CWC(DA),25Dx25Dx30ST,7kgf/cm2,[CDUK25-30D-A93L/SMC],FOR CHARPY IMPACT TESTER(BURR REMOVER),OR EQUIVALENT | L5: EA | M5: STANDARD | N5: CDUK25-30D-A93L | O5: SMC | R5: NONE | X5: FOR CHARPY IMPACT TESTER(BURR REMOVER) | AB5: _SMC_CDUK25-30D-A93L_CATALOG_20250526111558421.pdf | AE5: https://www.smckorea.co.kr/ | AH5: SMC_CDUK25-30D-A93L_20250526111854632.jpg | AJ5: 권우석 | AK5: (포항)품질기술부 재질시험섹션 | AL5: kws80395@posco.co.kr | AM5: 박민우 | AN5: (포항)품질기술부 재질시험섹션 | AO5: cinnamon@posco.co.kr | AP5: 2025-05-28 13:05:15 | AQ5: 2025 | AR5: 차후 재점검 | AS5: 기 설치된 물품의 호환성을 위해 특정 사양으로 등록건 확인,_x000D_ Q4594812등 유사item 검색하였으나, 유사/동일품 없음 확인후 승인합니다._x000D_ (특정 사양품감축 관련) 차후 입고시 스케치, 현물 확인을 통한 도면화, 일반 사양화, 복수화 전환 검토 요청 필히 부탁드립니다. 감사합니다._x000D_ | AT5: N
A6: Q4688206 | B6: 0 | C6: 포스코 | D6: Pneumatic Cylinder | E6: Pneumatic Cylinder | F6: 전아람 | G6: 특정사양품(단수) | H6: ACTIVE | I6: L | J6: KRW | K6: CWC(DA),SD,50Dx20Dx100ST,10.2kgf/cm2,[CDQ2A50-100DCZ-M9BWL/SMC],OR EQUIVALENT | L6: EA | M6: STANDARD | N6: CDQ2A50-100DCZ-M9BWL | O6: SMC | R6: NONE | AB6: 16. 특정사양품(신규등록) 품의서(CDQ2A50-100DCZ-M9BWL)_20250924145804115.docx | AE6: https://www.smckorea.co.kr/ | AH6: 16. Pneumatic Valve (공압 밸브)_20250924145312817.jpg | AJ6: 정석운 | AK6: 설비자재구매실 자재구매그룹 광양자재지원섹션 | AL6: sambar@posco.co.kr | AM6: 김선재 | AN6: 설비자재구매실 자재구매그룹 광양자재지원섹션 | AO6: jae7668@posco.co.kr | AP6: 2025-09-24 17:09:00 | AQ6: 2025 | AR6: 차후 재점검 | AS6: 기 설치된 물품의 호환성을 위해 특정 사양으로 등록건 확인, _x000D_ 유사 item 검색하였으나, 유사/동일품 없음 확인후 승인합니다._x000D_ (특정 사양품감축 관련) 차후 입고시 스케치, 현물 확인을 통한 도면화, 일반 사양화, 복수화 전환 검토 요청 부탁드립니다. 감사합니다._x000D_ | AT6: N
A7: Q4683457 | B7: 0 | C7: 포스코 | D7: Pneumatic Cylinder | E7: Pneumatic Cylinder | F7: 전아람 | G7: 특정사양품(단수) | H7: ACTIVE | I7: L | J7: KRW | K7: CA,100Dx30Dx300ST,10kgf/cm2,[CA2B100-300Z/SMC],2FINEX RTO,OR EQUIVALENT | L7: SET | M7: STANDARD | N7: CA2B100-300Z | O7: SMC | R7: NONE | X7: 2FINEX RTO | AB7: 250812_A2_제선설비부_물품등록자료_T1663035 2FINEX RTO Pneumatic Cylinder CA2B100-300Z Catalog_20250812185026609.pdf | AE7: https://www.smcpneumatics.com/CA2B100-300Z.html | AH7: 250812_A2_제선설비부_물품등록자료_T1663035 2FINEX RTO Pneumatic Cylinder CA2B100-300Z image_20250812185329161.jpg | AJ7: 문승준 | AK7: (포항)제선설비부 2FINEX정비섹션 | AL7: m130508@posco.co.kr | AM7: 김황식 | AN7: (포항)제선설비부 2FINEX정비섹션 | AO7: afang@posco.co.kr | AP7: 2025-08-13 07:08:01 | AQ7: 2025 | AR7: 차후 재점검 | AT7: N
A8: Q4501288 | B8: 0 | C8: 포스코 | D8: Pneumatic Cylinder | E8: Hydraulic & Pneumatics | F8: 전아람 | G8: 특정사양품(단수) | H8: ACTIVE | I8: L | J8: KRW | K8: CWC(DA),160Dx100ST,[CS1CN160-100-CJAD0046/SMC],FOR 1CGL #5,#6,#7 TENSION BRIDLE SNUBBER ROLL,OR EQUIVALENT | L8: EA | M8: STANDARD | N8: CS1CN160-100-CJAD0046 | O8: SMC | R8: NONE | X8: FOR 1CGL #5,#6,#7 TENSION BRIDLE SNUBBER ROLL | AB8: CS1CN160-100-CJAD0046(업그레이드 품)[1CGL 5.6.7 TB]_20220114112323273.pdf | AE8: http://www.smcpneumatics.com/pdfs/smc/70ACS1.pdf | AH8: 54TB_Roll_Snubber_R_sk2580_20201022_214208_20220114110512061.jpg | AJ8: 양병춘 | AK8: (광양)압연설비부 도금정비1섹션 | AM8: 김현호 | AN8: (광양)압연설비부 도금정비1섹션 | AO8: khh8352@posco.co.kr | AP8: 2022-01-17 08:01:57 | AQ8: 2022 | AR8: 차후 재점검 | AS8: 기 설치품의 사양 정보로 E-Catalog에 등록 하였으나 복수 참여 업체가 없어 자재 수급에 긴급성을 고려하여 기 설치품으로 물품 등록 하게 되었음. _x000D_ | AT8: N
A9: Q4661796 | B9: 0 | C9: 포스코 | D9: Pneumatic Cylinder | E9: Pneumatic Cylinder | F9: 전아람 | G9: 특정사양품(단수) | H9: ACTIVE | I9: L | J9: KRW | K9: CWC(DA),CA,250Dx150ST,[CS1CN250-KRD0368-150/SMC],FOR K1APL NO.6 TBR SNUBBER ROLL UP/DOWN,OR EQUIVALENT | L9: SET | M9: STANDARD | N9: CS1CN250-KRD0368-150 | O9: SMC | R9: NONE | X9: FOR K1APL NO.6 TBR SNUBBER ROLL UP/DOWN | AB9: 6TBR SR SMC Pneumatic Cylinder 카탈로그_20250113100103768.png | AE9: https://www.smckorea.co.kr/ | AH9: SMC Pneumatic Cylinder 실물 사진_20250113100103847.png | AJ9: 박원준 | AK9: (광양)압연설비2부 전기강판정비섹션 | AL9: wjpark@posco.co.kr | AM9: 최인오 | AN9: (광양)압연설비2부 전기강판정비섹션 | AO9: choi6959@posco.co.kr | AP9: 2025-01-15 11:01:16 | AQ9: 2025 | AR9: 차후 재점검 | AS9: MRO e-Caltalog시스템 경유건으로 대체 Maker 미 발굴건, 기 설치된 Cylinder의 호환성을 위해 특정 사양으로 등록건 확인, _x000D_ Q4077013 등 유사 item 검색하였으나, 유사/동일품 없음 확인후 승인합니다. _x000D_ (특정 사양품감축 관련) 차후 입고시 스케치, 현물 확인을 통한 도면화,일반 사양화, 복수화 전환 검토 요청 필히 부탁드립니다. 감사합니다._x000D_ | AT9: N
A10: Q4550786 | B10: 0 | C10: 포스코 | D10: Pneumatic Cylinder | E10: Hydraulic & Pneumatics | F10: 전아람 | G10: 특정사양품(단수) | H10: ACTIVE | I10: L | J10: KRW | K10: FA,50Dx20Dx425ST,10kgf/cm2,[ACM-N-FA50-S425/KCC],OR EQUIVALENT | L10: SET | M10: STANDARD | N10: ACM-N-FA50-S425 | O10: KCC | R10: NONE | AB10: ACM_20220111135135572.pdf | AE10: https://www.kccpr.com/bbs/search.php?url=https%3A%2F%2Fwww.kccpr.com%2Fbbs%2Fsearch.php&stx=ACM | AH10: ACM_20220111135109104.jpg | AI10: Roll_Changing_Car_Air Cylinder_20220113105455723.jpg | AJ10: 이규연 | AK10: (포항)압연설비부 전기강판정비섹션 | AL10: lkydh@posco.co.kr | AM10: 이정욱 | AN10: (포항)압연설비부 전기강판정비섹션 | AO10: jw4102@posco.co.kr | AP10: 2022-02-09 08:02:06 | AQ10: 2022 | AR10: 불가피 품목 | AT10: N
A11: Q4549165 | B11: 0 | C11: 포스코 | D11: Pneumatic Cylinder | E11: Hydraulic & Pneumatics | F11: 전아람 | G11: 특정사양품(단수) | H11: ACTIVE | I11: L | J11: KRW | K11: CWC(DA),TC,80Dx25Dx125ST,10kgf/cm2,[ACM-N-TC80-S125-J/KCC],FOR CGL SHOT BLAST DUST COLLECTOR DOUBLE DAMPER PNEUMATIC CYLINDER,OR EQUIVALENT | L11: EA | M11: STANDARD | N11: ACM-N-TC80-S125-J | O11: KCC | R11: NONE | X11: FOR CGL SHOT BLAST DUST COLLECTOR DOUBLE DAMPER PNEUMATIC CYLINDER | AB11: ACM카달로그_20220119165138547.pdf | AE11: https://www.kccpr.com/bbs/search.php?url=https%3A%2F%2Fwww.kccpr.com%2Fbbs%2Fsearch.php&stx=ACM | AH11: ACM_20220119165114295.jpg | AJ11: 권인순 | AK11: (포항)압연설비부 냉연정비2섹션 | AM11: 신석현 | AN11: (포항)압연설비부 냉연정비2섹션 | AO11: sh01293@posco.co.kr | AP11: 2022-01-21 13:01:32 | AQ11: 2022 | AR11: 불가피 품목 | AT11: N
A12: Q4610700 | B12: 0 | C12: 포스코 | D12: Pneumatic Cylinder | E12: Pneumatic Cylinder | F12: 전아람 | G12: 특정사양품(단수) | H12: ACTIVE | I12: L | J12: KRW | K12: CWC(DA),TC,63Dx20Dx50ST,10kgf/cm2,[C96ST63-50-CJBG0810/SMC],OR EQUIVALENT | L12: SET | M12: STANDARD | N12: C96ST63-50-CJBG0810 | O12: SMC | R12: NONE | AB12: C96ST63-50-CJBG0810 도면_20230823093047288.jpg | AH12: C96_20230823092933535.jpg | AJ12: 이규연 | AK12: (포항)압연설비2부 전기강판정비섹션 | AL12: lkydh@posco.co.kr | AM12: 홍준모 | AN12: (포항)압연설비2부 전기강판정비섹션 | AO12: junmo01@posco.co.kr | AP12: 2023-08-28 09:08:40 | AQ12: 2023 | AR12: 차후 재점검 | AS12: MRO e-Caltalog시스템 경유건으로 대체 Maker 미 발굴건,3APL Side Trimmer Edge Support Roll의 핵심 부품으로 기 설치된 Pneumatic Cylinder의 호환성을 위해 특정 사양으로 등록건 확인 후 승인,(특정 사양품감축 관련) 차후 입고시 스케치, 현물 확인을 통한 도면화,일반 사양화,복수화 전환 검토 요청 필히 부탁드립니다. 감사합니다. | AT12: N
A13: Q4655802 | B13: 0 | C13: 포스코 | D13: Pneumatic Cylinder | E13: Pneumatic Cylinder | F13: 전아람 | G13: 특정사양품(단수) | H13: ACTIVE | I13: L | J13: KRW | K13: CWC(DA),TA,80Dx50Dx200ST,10kgf/cm2,[CDA2T80-KRT09KO-200Z-A54L3/SMC],FOR K1SMP 1RH SAMPLING PROBE LOADING CLAMP ROTATE,OR EQUIVALENT | L13: EA | M13: STANDARD | N13: CDA2T80-KRT09KO-200Z-A54L3 | O13: SMC | R13: NONE | X13: FOR K1SMP 1RH SAMPLING PROBE LOADING CLAMP ROTATE | AB13: Pneumatic cylinder CDA2T80-KRT09KO-200Z-A54L3 SMC_20241112142525736.pdf | AE13: https://www.smckorea.co.kr/ppis/data/catalog/CA2-Z.pdf | AH13: CDA2T80-KRT09KO-200Z-A54L3 대표사진_20241105115621263.PNG | AJ13: 남태현 | AK13: (광양)제강설비부 제강정비섹션 | AM13: 구건웅 | AN13: (광양)제강설비부 제강정비섹션 | AO13: kkkunwoong@posco.co.kr | AP13: 2024-11-13 15:11:56 | AQ13: 2024 | AR13: 차후 재점검 | AT13: N
A14: Q4609636 | B14: 0 | C14: 포스코 | D14: Pneumatic Cylinder | E14: Pneumatic Cylinder | F14: 전아람 | G14: 특정사양품(단수) | H14: ACTIVE | I14: L | J14: KRW | K14: CWC(DA),FA,100Dx30Dx115ST,10kgf/cm2,[CA2F100-KRT10KO-115Z-W-XC5/SMC],FOR K1APL FURNACE ENTRY SEAL ROLL UP & DOWN PNEUMATIC CYLINDER,OR EQUIVALENT | L14: SET | M14: STANDARD | N14: CA2F100-KRT10KO-115Z-W-XC5 | O14: SMC | R14: NONE | X14: FOR K1APL FURNACE ENTRY SEAL ROLL UP & DOWN PNEUMATIC CYLINDER | AB14: CA2-KRT 품명자료_20230816110159236.jpg, CA2F100-KRT10KO-115Z-W-XC5_20230816110208727.jpg | AE14: https://www.smckorea.co.kr/ | AH14: CA2_20230816110138500.jpg | AJ14: 정정현 | AK14: (광양)압연설비2부 전기강판정비섹션 | AL14: wjd1670@posco.co.kr | AM14: 박원준 | AN14: (광양)압연설비2부 전기강판정비섹션 | AO14: wjpark@posco.co.kr | AP14: 2023-08-18 10:08:16 | AQ14: 2023 | AR14: 차후 재점검 | AS14: MRO e-Caltalog시스템 경유건으로 대체 Maker 미 발굴건,K1APL FURNACE ENTRY SEAL ROLL UP & DOWN PNEUMATIC CYLINDER로 기 설치된 Pneumatic Cylinder의 호환성을 위해 특정 사양으로 등록건 확인 후 승인,(특정 사양품감축 관련) 차후 입고시 스케치, 현물 확인을 통한 도면화,일반 사양화,복수화 전환 검토 요청 필히 부탁드립니다. 감사합니다._x000D_ | AT14: N
A15: Q4592849 | B15: 0 | C15: 포스코 | D15: Pneumatic Cylinder | E15: Pneumatic Cylinder | F15: 전아람 | G15: 특정사양품(단수) | H15: ACTIVE | I15: L | J15: KRW | K15: CWC(DA),TC,63Dx20Dx1100ST,[CA2T63-1100Z-XC14/SMC],FOR 1CGL BANDING MACHINE LOWER CHUTE CYLINDER,OR EQUIVALENT | L15: EA | M15: STANDARD | N15: CA2T63-1100Z-XC14 | O15: SMC | R15: NONE | X15: FOR 1CGL BANDING MACHINE LOWER CHUTE CYLINDER | AB15: CA2T63-1100Z-XC14 도면_20230309101205940.jpg | AE15: https://www.smckorea.co.kr | AH15: CA2T63-1100Z-XC14 도면_20230308172157076.jpg | AJ15: 김응백 | AK15: (포항)압연설비2부 냉연정비2섹션 | AL15: kebe12@posco.co.kr | AM15: 박동방석 | AN15: (포항)압연설비2부 냉연정비2섹션 | AP15: 2023-03-13 09:03:48 | AQ15: 2023 | AR15: 차후 재점검 | AS15: MRO e-Caltalog시스템 공급사 소개건으로 대체 Maker 미 발굴건, 기 설치된 Pneumatic Cylinder의 호환성을 위해 특정 사양으로 등록건 확인 후 승인,_x000D_ (특정 사양품감축 관련) 차후 입고시 스케치, 현물 확인을 통한 도면화,일반 사양화,복수화 전환 검토 요청 필히 부탁드립니다. 감사합니다. | AT15: N
A16: Q4627759 | B16: 0 | C16: 포스코 | D16: Pneumatic Cylinder | E16: Pneumatic Cylinder | F16: 전아람 | G16: 특정사양품(단수) | H16: ACTIVE | I16: L | J16: KRW | K16: CWC(DA),TC,80Dx80Dx150ST,[CA2YT80-150Z-W/SMC],FOR K4H DC0~2 PINCH ROLL POLISHER AIR CYLINDER,OR EQUIVALENT | L16: EA | M16: STANDARD | N16: CA2YT80-150Z-W | O16: SMC | R16: NONE | X16: FOR K4H DC0~2 PINCH ROLL POLISHER AIR CYLINDER | AB16: CA2Y 카다로그_20240122135108312.pdf | AH16: CA2YT 시리즈 사진_20240122135032098.PNG | AJ16: 김성겸 | AK16: (광양)압연설비1부 열연정비2섹션 | AL16: sk_kim@posco.co.kr | AM16: 유두현 | AN16: (광양)압연설비1부 열연정비2섹션 | AO16: r2dhlove@posco.co.kr | AP16: 2024-01-30 16:01:55 | AQ16: 2024 | AR16: 차후 재점검 | AS16: MRO e-Caltalog시스템 경유건으로 대체 Maker 미 발굴건, 기 설치된 Cylinder의 호환성을 위해 특정 사양으로 등록건 확인_x000D_ Q4458267등 유사사양 확인 후 stroke 길이 상이 등으로 승인. | AT16: N
A17: Q4602359 | B17: 0 | C17: 포스코 | D17: Pneumatic Cylinder | E17: Pneumatic Cylinder | F17: 전아람 | G17: 특정사양품(단수) | H17: ACTIVE | I17: L | J17: KRW | K17: CWC(DA),CA,63Dx20Dx300ST,[CDA2C63-KRT09JO-300Z-W-A54/SMC],FOR CGL OVEN FUME EXHAUST FAN DAMPER CYLINDER,OR EQUIVALENT | L17: EA | M17: STANDARD | N17: CDA2C63-KRT09JO-300Z-W-A54 | O17: SMC | R17: NONE | X17: FOR CGL OVEN FUME EXHAUST FAN DAMPER CYLINDER | AB17: CDA2C63-KRT09JO-300Z-W-A54 도면_20230322090536209.jpg | AE17: https://www.smckorea.co.kr/ | AH17: CDA2C63-KRT09JO-300Z-W-A54 도면_20230322090505368.jpg | AJ17: 김응백 | AK17: (포항)압연설비2부 냉연정비2섹션 | AL17: kebe12@posco.co.kr | AM17: 김동환 | AN17: (포항)압연설비2부 냉연정비2섹션 | AO17: nakdhs@posco.co.kr | AP17: 2023-06-09 10:06:57 | AQ17: 2023 | AR17: 차후 재점검 | AS17: MRO e-Caltalog시스템 공급사 소개건으로 대체 Maker 미 발굴건,기 설치된 Pneumatic Cylinder의 호환성을 위해 특정 사양으로 등록건 확인 후 승인,_x000D_ (특정 사양품감축 관련) 차후 입고시 스케치, 현물 확인을 통한 도면화,일반 사양화,복수화 전환 검토 요청 필히 부탁드립니다. 감사합니다. | AT17: N
A18: Q4580829 | B18: 0 | C18: 포스코 | D18: Pneumatic Cylinder | E18: Pneumatic Cylinder | F18: 전아람 | G18: 특정사양품(단수) | H18: ACTIVE | I18: L | J18: KRW | K18: 40Dx16Dx450ST,[CDA2F40-450Z-Z73/SMC],FOR P1H HSL LABEL MACHINE FEEDER PNEUMATIC CYLINDER,OR EQUIVALENT | L18: EA | M18: STANDARD | N18: CDA2F40-450Z-Z73 | O18: SMC | R18: NONE | X18: FOR P1H HSL LABEL MACHINE FEEDER PNEUMATIC CYLINDER | AB18: cda2f40-450z-z73_20221123105810184.jpg | AE18: https://www.smckorea.co.kr/ppis/data/catalog/CA2-Z.pdf | AH18: CDA2_20221123105527252.jpg | AJ18: 조규호 | AK18: (포항)압연설비부 열연정비섹션 | AL18: kyuho85@posco.co.kr | AM18: 이일하 | AN18: (포항)압연설비부 열연정비섹션 | AP18: 2022-11-25 08:11:02 | AQ18: 2022 | AR18: 불가피 품목 | AT18: N
A19: Q4611126 | B19: 0 | C19: 포스코 | D19: Pneumatic Cylinder | E19: Hydraulic & Pneumatics | F19: 전아람 | G19: 특정사양품(단수) | H19: ACTIVE | I19: L | J19: KRW | K19: CWD,TC,100Dx30Dx420ST,[CDA2T100-420Z-A93L-XC14/SMC],OR EQUIVALENT | L19: SET | M19: STANDARD | N19: CDA2T100-420Z-A93L-XC14 | O19: SMC | R19: NONE | AB19: CDA2T100-420Z-A93L-XC14도면_20230822112542085.jpg | AE19: https://www.smckorea.co.kr/esales/data/sangpum/kisul_qa/2023KS008009/CDA2T100-420Z-A93L-XC14.pdf | AH19: CA2_20230822112503791.jpg | AJ19: 김영민 | AK19: (포항)압연설비1부 선재정비섹션 | AL19: dudals9563@posco.co.kr | AM19: 김강민 | AN19: (포항)압연설비1부 선재정비섹션 | AO19: inhachris768@posco.co.kr | AP19: 2023-08-30 13:08:39 | AQ19: 2023 | AR19: 차후 재점검 | AS19: MRO e-Caltalog시스템 경유건으로 대체 Maker 미 발굴건,기 설치된 Pneumatic Cylinder의 호환성을 위해 특정 사양으로 등록건 확인 후 승인,_x000D_ (특정 사양품감축 관련) 차후 입고시 스케치, 현물 확인을 통한 도면화,일반 사양화,복수화 전환 검토 요청 필히 부탁드립니다. 감사합니다._x000D_ | AT19: N
A20: Q4504927 | B20: 0 | C20: 포스코퓨처엠 | D20: Pneumatic Cylinder | E20: Pneumatic Cylinder | F20: 전아람 | G20: 특정사양품(단수) | H20: ACTIVE | I20: L | J20: KRW | K20: CWC(DA),TC,40Dx16Dx125ST,10kgf/cm2,[CDA2T40-125Z-NW-M9BW/SMC] | L20: SET | M20: STANDARD | N20: CDA2T40-125Z-NW-M9BW | O20: SMC | R20: NONE | AB20: CDA2T40-T125Z_20200402103822497.png | AE20: https://www.smckorea.co.kr/ | AH20: 1_20241014165711546.JPG | AJ20: 황 성욱 | AK20: 음극소재사업소 | AL20: hwangsw@poscofuturem.com | AM20: 이 승권 | AN20: 음극재정비섹션 | AO20: tmdrnjs0809@poscofuturem.com | AP20: 2024-10-16 10:10:40 | AQ20: 2024 | AR20: 차후 재점검 | AT20: N
A21: Q4669390 | B21: 0 | C21: 포스코 | D21: Pneumatic Cylinder | E21: Pneumatic Cylinder | F21: 전아람 | G21: 특정사양품(단수) | H21: ACTIVE | I21: L | J21: KRW | K21: CWC(DA),CA,125Dx90Dx350ST,15kgf/cm2,[CDS1CN125-KRD0368-350-A54L/SMC],MAKER DWG NO:CDS1CN125-KRD0368-350-A54L,OR EQUIVALENT | L21: EA | M21: STANDARD | N21: CDS1CN125-KRD0368-350-A54L | O21: SMC | R21: NONE | W21: MAKER DWG NO:CDS1CN125-KRD0368-350-A54L | AB21: CDS1CN125-KRD0368-350-A54L 도면_20250325141804318.pdf | AE21: https://www.smckorea.co.kr/ppis/data/catalog/CS1.pdf | AH21: CDS1CN125-KRD0368-350-A54L 대표사진_20250325141743709.png | AJ21: 김형종 | AK21: (광양)압연설비2부 도금정비2섹션 | AL21: naju68@posco.co.kr | AM21: 이태호 | AN21: (광양)압연설비2부 도금정비2섹션 | AO21: leetaeho0411@posco.co.kr | AP21: 2025-04-02 10:04:28 | AQ21: 2025 | AR21: 차후 재점검 | AS21: MRO e-Caltalog시스템 경유건으로 대체 Maker 미 발굴건, 기 설치된 CYLINDER의 호환성을 위해 특정 사양으로 등록건 확인,_x000D_ Q4096129등 유사item 검색하였으나, 유사/동일품 없음 확인후 승인합니다._x000D_ (특정 사양품감축 관련) 차후 입고시 스케치, 현물 확인을 통한 도면화, 일반 사양화, 복수화 전환 검토 요청 필히 부탁드립니다. 감사합니다._x000D_ | AT21: N
A22: Q4629827 | B22: 0 | C22: 포스코 | D22: Pneumatic Cylinder | E22: Pneumatic Cylinder | F22: 전아람 | G22: 특정사양품(단수) | H22: ACTIVE | I22: L | J22: KRW | K22: 125Dx727Dx500ST,9.7kgf/cm2,[CDS1TN125-KRD0368-500-Z73L/SMC],MAKER DWG NO:CDS1TN125-KRD0368-500-Z73L,OR EQUIVALENT | L22: SET | M22: STANDARD | N22: CDS1TN125-KRD0368-500-Z73L | O22: SMC | R22: NONE | W22: MAKER DWG NO:CDS1TN125-KRD0368-500-Z73L | AB22: CDS1TN125-KRD0368-500-Z73L_20240109111550766.pdf | AH22: cds1_20240109111427520.png | AJ22: 민병찬 | AK22: (포항)제강설비부 제강정비섹션 | AL22: clazziquai@posco.co.kr | AM22: 김대철 | AN22: (포항)제강설비부 제강정비섹션 | AO22: kim.7@posco.co.kr | AP22: 2024-02-20 14:02:50 | AQ22: 2024 | AR22: 차후 재점검 | AT22: N
A23: Q4627207 | B23: 0 | C23: 포스코 | D23: Pneumatic Cylinder | E23: Pneumatic Cylinder | F23: 전아람 | G23: 특정사양품(단수) | H23: ACTIVE | I23: L | J23: KRW | K23: CWC(DA),CA,200Dx200Dx220ST,16kgf/cm2,[CDS2T200-200-CJCD0039/SMC],OR EQUIVALENT | L23: EA | M23: STANDARD | N23: CDS2T200-200-CJCD0039 | O23: SMC | R23: NONE | AB23: CDS2T200-200-CJCD0039_20240117110145614.pdf | AH23: cs2 실린더_20240117105756959.PNG | AJ23: 홍성현 | AK23: 광양생산부 정비섹션 | AM23: 이현우 | AN23: 광양생산부 정비섹션 | AO23: 2hyunwoo@posco.co.kr | AP23: 2024-01-25 11:01:22 | AQ23: 2024 | AR23: 차후 재점검 | AS23: MRO e-Caltalog시스템 경유건으로 대체 Maker 미 발굴건, 기 설치된 Cylinder의 호환성을 위해 특정 사양으로 등록건 확인 후 승인,_x000D_ 유사사양 확인함._x000D_ | AT23: N
A24: Q4636670 | B24: 0 | C24: 포스코 | D24: Pneumatic Cylinder | E24: Pneumatic Cylinder | F24: 전아람 | G24: 특정사양품(단수) | H24: ACTIVE | I24: L | J24: KRW | K24: CWC(DA),CA,320Dx320Dx250ST,[CDS2T320-250-CJCD0239/SMC],MAKER DWG NO:CDS2T320-250-CJCD0239,OR EQUIVALENT | L24: EA | M24: STANDARD | N24: CDS2T320-250-CJCD0239 | O24: SMC | R24: NONE | W24: MAKER DWG NO:CDS2T320-250-CJCD0239 | AB24: CDS2T320-250-CJCD0239_20240424160715569.pdf | AH24: cs2 실린더_20240424160715682.PNG | AJ24: 홍성현 | AK24: 광양생산부 정비섹션 | AM24: 이현우 | AN24: 광양생산부 정비섹션 | AO24: 2hyunwoo@posco.co.kr | AP24: 2024-04-25 08:04:39 | AQ24: 2024 | AR24: 차후 재점검 | AS24: Q4627207등 유사item 검색하였으나, Boa Size상이로 확인하고 승인합니다. | AT24: N
A25: Q4680486 | B25: 0 | C25: 포스코 | D25: Pneumatic Cylinder | E25: Pneumatic Cylinder | F25: 전아람 | G25: 특정사양품(단수) | H25: ACTIVE | I25: L | J25: KRW | K25: CWC(DA),CA,63Dx20Dx64ST,10kgf/cm2,[CG1DN63-64-CJD00567/SMC],MAKER DWG NO:CG1DN63-64-CJD00567,FOR K1C 3RCL OILER DRIP PAN SWING CYLINDER,OR EQUIVALENT | L25: EA | M25: STANDARD | N25: CG1DN63-64-CJD00567 | O25: SMC | R25: NONE | W25: MAKER DWG NO:CG1DN63-64-CJD00567 | X25: FOR K1C 3RCL OILER DRIP PAN SWING CYLINDER | AB25: CG1DN63-64-CJD00567_20250717071148728.pdf | AE25: https://www.smckorea.co.kr/ppis/data/domyun/CJD00567-AP..pdf | AH25: CG1_20250717071148769.jpg | AJ25: 이현식 | AK25: (광양)압연설비2부 냉연정비2섹션 | AL25: lee388@posco.co.kr | AM25: 최용석 | AN25: (광양)압연설비2부 냉연정비2섹션 | AO25: choiyongsuk@posco.co.kr | AP25: 2025-07-17 09:07:26 | AQ25: 2025 | AR25: 차후 재점검 | AS25: 기 설치된 물품의 호환성을 위해 특정 사양으로 등록건 확인,_x000D_ Q2230732등 유사item 검색하였으나, 유사/동일품 없음 확인후 승인합니다._x000D_ (특정 사양품감축 관련) 차후 입고시 스케치, 현물 확인을 통한 도면화, 일반 사양화, 복수화 전환 검토 요청 부탁드립니다. 감사합니다._x000D_ _x000D_ | AT25: N
A26: Q4609635 | B26: 0 | C26: 포스코 | D26: Pneumatic Cylinder | E26: Pneumatic Cylinder | F26: 전아람 | G26: 특정사양품(단수) | H26: ACTIVE | I26: L | J26: KRW | K26: CWC(DA),CF,40Dx14Dx40ST,10kgf/cm2,[CM2B40-40Z/SMC],FOR K1APL EXIT SEAL ROLL UPPER/LOWER SEAL PACKING OPEN/CLOSE,OR EQUIVALENT | L26: SET | M26: STANDARD | N26: CM2B40-40Z | O26: SMC | R26: NONE | X26: FOR K1APL EXIT SEAL ROLL UPPER/LOWER SEAL PACKING OPEN/CLOSE | AB26: CM2_20230816105642860.jpg | AE26: https://www.smckorea.co.kr/ppis/data/catalog/CM2-Z.pdf | AH26: CM2_20230816105623524.jpg | AJ26: 정정현 | AK26: (광양)압연설비2부 전기강판정비섹션 | AL26: wjd1670@posco.co.kr | AM26: 박원준 | AN26: (광양)압연설비2부 전기강판정비섹션 | AO26: wjpark@posco.co.kr | AP26: 2023-08-18 10:08:01 | AQ26: 2023 | AR26: 차후 재점검 | AS26: MRO e-Caltalog시스템 경유건으로 대체 Maker 미 발굴건,K1APL EXIT SEAL ROLL UPPER/LOWER SEAL PACKING OPEN/CLOSE로 기 설치된 Pneumatic Cylinder의 호환성을 위해 특정 사양으로 등록건 확인 후 승인,(특정 사양품감축 관련) 차후 입고시 스케치, 현물 확인을 통한 도면화,일반 사양화,복수화 전환 검토 요청 필히 부탁드립니다. 감사합니다. | AT26: N
A27: Q4649046 | B27: 0 | C27: 포스코 | D27: Pneumatic Cylinder | E27: Pneumatic Cylinder | F27: 전아람 | G27: 특정사양품(단수) | H27: ACTIVE | I27: L | J27: KRW | K27: CWC(DA),CC,40Dx14Dx350ST,10kgf/cm2,[CDBM2B40-350-HN-A93/SMC],FOR 3CAL SAMPLE MACHINE "Y" HEAD,OR EQUIVALENT | L27: EA | M27: STANDARD | N27: CDBM2B40-350-HN-A93 | O27: SMC | R27: NONE | X27: FOR 3CAL SAMPLE MACHINE "Y" HEAD | AB27: CM2엔드락_20240808163226993.jpg | AE27: https://www.smckorea.co.kr/ppis/data/catalog/CM2-Z.pdf | AH27: CM2엔드락_20240808163208789.jpg | AJ27: 김응백 | AK27: (포항)압연설비2부 냉연정비2섹션 | AL27: kebe12@posco.co.kr | AM27: 왕우현 | AN27: (포항)압연설비2부 냉연정비2섹션 | AO27: dngus0503@posco.co.kr | AP27: 2024-09-02 11:09:47 | AQ27: 2024 | AR27: 차후 재점검 | AT27: N
A28: Q4697437 | B28: 0 | C28: 포스코 | D28: Pneumatic Cylinder | E28: Pneumatic Cylinder | F28: 전아람 | G28: 특정사양품(단수) | H28: ACTIVE | I28: L | J28: KRW | K28: CWC(DA),TC,200Dx246ST,[CDS1TN200-246K-A54/SMC],OR EQUIVALENT | L28: SET | M28: STANDARD | N28: CDS1TN200-246K-A54 | O28: SMC | Q28: UNKNOWN | R28: NONE | T28: UNKNOWN | U28: NONE | AB28: CS1_20260106170106839.pdf | AH28: CS1LN125-KRT04KO-600_20260106171938339.png | AJ28: 구건웅 | AK28: (광양)제강설비부 제강정비섹션 | AL28: kkkunwoong@posco.co.kr | AM28: 구건웅 | AN28: (광양)제강설비부 제강정비섹션 | AO28: kkkunwoong@posco.co.kr | AP28: 2026-01-07 08:01:32 | AQ28: 2026 | AR28: 차후 재점검 | AS28: 기 설치된 물품의 호환성을 위해 특정 사양으로 등록건 확인, 유사 item 검색하였으나, 유사/동일품 없음 확인후 승인합니다. (특정 사양품감축 관련) 차후 입고시 스케치, 현물 확인을 통한 도면화, 일반 사양화, 복수화 전환 검토 요청 부탁드립니다. 감사합니다. | AT28: N
A29: Q4609854 | C29: 포스코 | D29: Pneumatic Cylinder | E29: Pneumatic Cylinder | F29: 전아람 | G29: 특정사양품(단수) | H29: ACTIVE | I29: L | J29: KRW | K29: CWC(DA),TD,300Dx70Dx550ST,10kgf/cm2,[CS1C0-VOA003-550/SMC],FOR K1APL COOLING DEVICE UPPER CASING UP/DOWN PNEUMATIC CYLINDER,OR EQUIVALENT | L29: SET | M29: STANDARD | N29: CS1C0-VOA003-550 | O29: SMC | R29: NONE | X29: FOR K1APL COOLING DEVICE UPPER CASING UP/DOWN PNEUMATIC CYLINDER | AB29: CS1C0-VOA003-550 사양서_20230816104357707.jpg | AH29: CS1_20230816104334033.jpg | AJ29: 정정현 | AK29: (광양)압연설비2부 전기강판정비섹션 | AL29: wjd1670@posco.co.kr | AM29: 박원준 | AN29: (광양)압연설비2부 전기강판정비섹션 | AO29: wjpark@posco.co.kr | AP29: 2023-08-21 09:08:14 | AQ29: 2023 | AR29: 차후 재점검 | AS29: MRO e-Caltalog시스템 경유건으로 대체 Maker 미 발굴건,K1APL STRIP COOLING DEVICE 의 핵심 부품으로 기 설치된 Pneumatic Cylinder의 호환성을 위해 특정 사양으로 등록건 확인 후 승인,(특정 사양품감축 관련) 차후 입고시 스케치, 현물 확인을 통한 도면화,일반 사양화,복수화 전환 검토 요청 필히 부탁드립니다. 감사합니다. | AT29: N
A30: Q4609677 | C30: 포스코 | D30: Pneumatic Cylinder | E30: Hydraulic & Pneumatics | F30: 전아람 | G30: 특정사양품(단수) | H30: ACTIVE | I30: L | J30: KRW | K30: CWC(DA),CD,140Dx36Dx135ST,10kgf/cm2,[CS1CN140-KRT04KO-135-XC5/SMC],FOR K1APL STRIP GRIPPER UP/DOWN PNEUMATIC CYLINDER,OR EQUIVALENT | L30: SET | M30: STANDARD | N30: CS1CN140-KRT04KO-135-XC5 | O30: SMC | R30: NONE | X30: FOR K1APL STRIP GRIPPER UP/DOWN PNEUMATIC CYLINDER | AB30: CS1CN140-KRT04KO-135-XC5_20230818130538338.jpg | AH30: CS1_20230816104955978.jpg | AJ30: 정정현 | AK30: (광양)압연설비2부 전기강판정비섹션 | AL30: wjd1670@posco.co.kr | AM30: 박원준 | AN30: (광양)압연설비2부 전기강판정비섹션 | AO30: wjpark@posco.co.kr | AP30: 2023-08-18 13:08:25 | AQ30: 2023 | AR30: 차후 재점검 | AS30: MRO e-Caltalog시스템 경유건으로 대체 Maker 미 발굴건,K1APL STRIP GRIPPER UP/DOWN PNEUMATIC CYLINDER로 기 설치된 Pneumatic Cylinder의 호환성을 위해 특정 사양으로 등록건 확인 후 승인,(특정 사양품감축 관련) 차후 입고시 스케치, 현물 확인을 통한 도면화,일반 사양화,복수화 전환 검토 요청 필히 부탁드립니다. 감사합니다.(현장 Name Plate사진으로 사양 확인건) | AT30: N
A31: Q4608549 | C31: 포스코 | D31: Pneumatic Cylinder | E31: Pneumatic Cylinder | F31: 전아람 | G31: 특정사양품(단수) | H31: ACTIVE | I31: L | J31: KRW | K31: CWC(DA),CB,200Dx50Dx150ST,10kgf/cm2,[CS1CN200-KRD0368-150/SMC],FOR K1APL NO.3 TENSION BRIDLE ROLL SNUBBER ROLL UP & DOWN PNEUMATIC CYLINDER,OR EQUIVALENT | L31: SET | M31: STANDARD | N31: CS1CN200-KRD0368-150 | O31: SMC | R31: NONE | X31: FOR K1APL NO.3 TENSION BRIDLE ROLL SNUBBER ROLL UP & DOWN PNEUMATIC CYLINDER | AB31: CS1CN200-KRD0368-150_20230807164932049.jpg | AE31: https://www.smckorea.co.kr/ppis/data/catalog/CS1.pdf | AH31: Cylinder_20230807165018060.jpg | AJ31: 정정현 | AK31: (광양)압연설비2부 전기강판정비섹션 | AL31: wjd1670@posco.co.kr | AM31: 박원준 | AN31: (광양)압연설비2부 전기강판정비섹션 | AO31: wjpark@posco.co.kr | AP31: 2023-08-08 11:08:11 | AQ31: 2023 | AR31: 차후 재점검 | AS31: MRO e-Caltalog시스템 경유건으로 대체 Maker 미 발굴건,K1APL NO.3 TENSION BRIDLE ROLL SNUBBER ROLL UP & DOWN PNEUMATIC CYLINDER로 기 설치된 Pneumatic Cylinder의 호환성을 위해 특정 사양으로 등록건 확인 후 승인,(특정 사양품감축 관련) 차후 입고시 스케치, 현물 확인을 통한 도면화,일반 사양화,복수화 전환 검토 요청 필히 부탁드립니다. 감사합니다. | AT31: N
A32: Q4660031 | C32: 포스코 | D32: Pneumatic Cylinder | E32: Pneumatic Cylinder | F32: 전아람 | G32: 특정사양품(단수) | H32: ACTIVE | I32: L | J32: KRW | K32: 250Dx60Dx830ST,[CS1D250-KRD0368-830/SMC],FOR K3H SCRAP CHUTE LIFT,OR EQUIVALENT | L32: EA | M32: STANDARD | N32: CS1D250-KRD0368-830 | O32: SMC | R32: NONE | X32: FOR K3H SCRAP CHUTE LIFT | AB32: cs1d250_20241218132730514.png | AE32: https://www.smckorea.co.kr/homepage/ver3.5/product/catalogue_sub_detail.asp?cata_no=914 | AH32: 캡처1_20250226141148414.png | AJ32: 김성겸 | AK32: (광양)압연설비1부 열연정비2섹션 | AL32: sk_kim@posco.co.kr | AM32: 양승국 | AN32: (광양)압연설비1부 열연정비2섹션 | AO32: skystc1997@posco.co.kr | AP32: 2025-02-27 13:02:36 | AQ32: 2025 | AR32: 차후 재점검 | AS32: Q4020093등 유사item 검색하였으나, stroke등 상이함 확인후 승인합니다. | AT32: N
A33: Q4608555 | C33: 포스코 | D33: Pneumatic Cylinder | E33: Pneumatic Cylinder | F33: 전아람 | G33: 특정사양품(단수) | H33: ACTIVE | I33: L | J33: KRW | K33: CWC(DA),CB,250Dx60Dx400ST,10kgf/cm2,[CS1CN250-KRD0368-400/SMC],FOR K1APL NO.10 STEERING ROLL UP & DOWN PNEUMATIC CYLINDER,OR EQUIVALENT | L33: SET | M33: STANDARD | N33: CS1CN250-KRD0368-400 | O33: SMC | R33: NONE | X33: FOR K1APL NO.10 STEERING ROLL UP & DOWN PNEUMATIC CYLINDER | AB33: CS1DN250-KRD0368-400 라벨_20230803111519273.jpg | AE33: https://www.smckorea.co.kr/ppis/data/catalog/CS1.pdf | AH33: Cylinder_20230807165711445.jpg | AJ33: 정정현 | AK33: (광양)압연설비2부 전기강판정비섹션 | AL33: wjd1670@posco.co.kr | AM33: 박원준 | AN33: (광양)압연설비2부 전기강판정비섹션 | AO33: wjpark@posco.co.kr | AP33: 2023-08-08 11:08:33 | AQ33: 2023 | AR33: 차후 재점검 | AS33: MRO e-Caltalog시스템 경유건으로 대체 Maker 미 발굴건,K1APL NO.10 STEERING ROLL UP & DOWN PNEUMATIC CYLINDER로 기 설치된 Pump의 호환성을 위해 특정 사양으로 등록건 확인 후 승인,(특정 사양품감축 관련) 차후 입고시 스케치, 현물 확인을 통한 도면화,일반 사양화,복수화 전환 검토 요청 필히 부탁드립니다. 감사합니다. | AT33: N
A34: Q4662387 | C34: 포스코 | D34: Pneumatic Cylinder | E34: Pneumatic Cylinder | F34: 전아람 | G34: 특정사양품(단수) | H34: ACTIVE | I34: L | J34: KRW | K34: CWC(DA),FA,180Dx45Dx80ST,9.9kgf/cm2,[CS1F180-80-KRHD0444/SMC],FOR 1CGL EXIT WRINGER ROLL OPEN&CLOSE CYLINDER,OR EQUIVALENT | L34: EA | M34: STANDARD | N34: CS1F180-80-KRHD0444 | O34: SMC | R34: NONE | X34: FOR 1CGL EXIT WRINGER ROLL OPEN&CLOSE CYLINDER | AB34: CS1F180-80-KRHD0444 도면_20250102163354322.pdf | AE34: https://www.smckorea.co.kr/esales/data/sangpum/kisul_qa/2024KS012656/KRHD0444-AP.pdf | AH34: CS1_20250102163143465.jpg | AI34: CS1F180-80-KRHD0444_SMC_20250116152515461.jpg | AJ34: 박광웅 | AK34: (광양)압연설비2부 도금정비1섹션 | AM34: 김대한 | AN34: (광양)압연설비2부 도금정비1섹션 | AP34: 2025-01-20 15:01:54 | AQ34: 2025 | AR34: 차후 재점검 | AS34: MRO e-Caltalog시스템 경유건으로 대체 Maker 미 발굴건, 기 설치된 Cylinder의 호환성을 위해 특정 사양으로 등록건 확인,_x000D_ Q4111676 등 유사item 검색하였으나, 유사/동일품 없음 확인후 승인합니다._x000D_ (특정 사양품감축 관련) 차후 입고시 스케치, 현물 확인을 통한 도면화,일반 사양화, 복수화 전환 검토 요청 필히 부탁드립니다. 감사합니다._x000D_ | AT34: N
A35: Q4636081 | C35: 포스코 | D35: Pneumatic Cylinder | E35: Pneumatic Cylinder | F35: 전아람 | G35: 특정사양품(단수) | H35: ACTIVE | I35: L | J35: KRW | K35: CWC(DA),FA,180Dx45Dx100ST,9.89kgf/cm2,[CS1FN180-KRT04JO-100/SMC],MAKER DWG NO:CS1FN180-KRT04JO-100,FOR 1EGL ACS & ARS WRINGER ROLL TOP PNEUMATIC CYLINDER,OR EQUIVALENT | L35: EA | M35: STANDARD | N35: CS1FN180-KRT04JO-100 | O35: SMC | R35: NONE | W35: MAKER DWG NO:CS1FN180-KRT04JO-100 | X35: FOR 1EGL ACS & ARS WRINGER ROLL TOP PNEUMATIC CYLINDER | AB35: CS1FN180-KRT04JO-100 도면_20240417162506734.pdf | AE35: https://www.smckorea.co.kr/ppis/data/catalog/CS1.pdf | AH35: CS1FN180-KRT04JO-100 대표_20240417162429494.PNG | AJ35: 박광웅 | AK35: (광양)압연설비2부 도금정비1섹션 | AM35: 박정규 | AN35: (광양)압연설비2부 도금정비1섹션 | AO35: pjk2540@posco.co.kr | AP35: 2024-04-19 09:04:43 | AQ35: 2024 | AR35: 차후 재점검 | AS35: Q4111676등 유사 item 검색하였으나, stroke등 상이하여 확인하고 승인합니다. | AT35: N
A36: Q4608565 | C36: 포스코 | D36: Pneumatic Cylinder | E36: Pneumatic Cylinder | F36: 전아람 | G36: 특정사양품(단수) | H36: ACTIVE | I36: L | J36: KRW | K36: CWC(DA),FE,200Dx50Dx150ST,10kgf/cm2,[CS1DN250-KRD0368-400/SMC],FOR K1APL FURNACE WCS DAM ROLL UP & DOWN PNEUMATIC CYLINDER,OR EQUIVALENT | L36: SET | M36: STANDARD | N36: CS1DN250-KRD0368-400 | O36: SMC | R36: NONE | X36: FOR K1APL FURNACE WCS DAM ROLL UP & DOWN PNEUMATIC CYLINDER | AB36: CS1FN200-KRT04KO-150-XC5 라벨_20230803111800907.jpg | AE36: https://www.smckorea.co.kr/ppis/data/catalog/CS1.pdf | AH36: Cylinder_20240116160853051.jpg | AJ36: 정정현 | AK36: (광양)압연설비2부 전기강판정비섹션 | AL36: wjd1670@posco.co.kr | AM36: 박원준 | AN36: (광양)압연설비2부 전기강판정비섹션 | AO36: wjpark@posco.co.kr | AP36: 2024-01-18 10:01:51 | AQ36: 2024 | AR36: 차후 재점검 | AS36: MRO e-Caltalog시스템 경유건으로 대체 Maker 미 발굴건,K1APL FURNACE WCS DAM ROLL UP & DOWN PNEUMATIC CYLINDER로 기 설치된 Pneumatic Cylinder의 호환성을 위해 특정 사양으로 등록건 확인 후 승인,(특정 사양품감축 관련) 차후 입고시 스케치, 현물 확인을 통한 도면화,일반 사양화,복수화 전환 검토 요청 필히 부탁드립니다. 감사합니다. | AT36: N
A37: Q4685560 | C37: 포스코 | D37: Pneumatic Cylinder | E37: Pneumatic Cylinder | F37: 전아람 | G37: 특정사양품(단수) | H37: ACTIVE | I37: L | J37: KRW | K37: 200Dx50Dx80ST,9.89kgf/cm2,[CS1FN200-KRT04KO-80/SMC],2APL PICKLE SQUEEZE ROLL UP/DOWN,OR EQUIVALENT | L37: SET | M37: STANDARD | N37: CS1FN200-KRT04KO-80 | O37: SMC | R37: NONE | X37: 2APL PICKLE SQUEEZE ROLL UP/DOWN | AB37: CS1FN200-KRT04KO-80_20250901145913989.pdf | AE37: https://www.smckorea.co.kr/homepage/ver3.5/product/catalogue_sub_detail.asp?no=914 | AH37: CS1_20250827152926703.jpg | AJ37: 김원길 | AK37: (포항)압연설비2부 STS압연정비섹션 | AL37: 855956@posco.co.kr | AM37: 정세훈 | AN37: (포항)압연설비2부 STS압연정비섹션 | AO37: sehun0129@posco.co.kr | AP37: 2025-09-02 16:09:21 | AQ37: 2025 | AR37: 차후 재점검 | AS37: 기 설치된 물품의 호환성을 위해 특정 사양으로 등록건 확인,_x000D_ 유사item 검색하였으나, 유사/동일품 없음 확인후 승인합니다._x000D_ (특정 사양품감축 관련) 차후 입고시 스케치, 현물 확인을 통한 도면화, 일반 사양화, 복수화 전환 검토 요청 부탁드립니다. 감사합니다._x000D_ | AT37: N
A38: Q4606860 | C38: 포스코 | D38: Pneumatic Cylinder | E38: Pneumatic Cylinder | F38: 전아람 | G38: 특정사양품(단수) | H38: ACTIVE | I38: L | J38: KRW | K38: CWC(DA),TD,160Dx40Dx140ST,9.7kgf/cm2,[CS1TN160-KRD0368-140-XC14A/SMC],FOR 1EGL WELDER DOWN PASS PINCH ROLL UP/DOWN CYLINDER,OR EQUIVALENT | L38: SET | M38: STANDARD | N38: CS1TN160-KRD0368-140-XC14A | O38: SMC | R38: NONE | X38: FOR 1EGL WELDER DOWN PASS PINCH ROLL UP/DOWN CYLINDER | AB38: CS1TN160-KRD0368-140-XC14A 도면_20230718114028531.jpg | AE38: https://www.smckorea.co.kr/ | AH38: CS1_20230718113831032.jpg | AJ38: 김응백 | AK38: (포항)압연설비2부 냉연정비2섹션 | AL38: kebe12@posco.co.kr | AM38: 백종수 | AN38: (포항)압연설비2부 냉연정비2섹션 | AO38: jongsu97@posco.co.kr | AP38: 2023-07-21 08:07:08 | AQ38: 2023 | AR38: 차후 재점검 | AS38: MRO e-Caltalog시스템 경유건으로 대체 Maker 미 발굴건,1EGL WELDER DOWN PASS PINCH ROLL UP/DOWN CYLINDER로 기 설치된 Pneumatic Cylinder의 호환성을 위해 특정 사양으로 등록건 확인 후 승인,(특정 사양품감축 관련) 차후 입고시 스케치, 현물 확인을 통한 도면화,일반 사양화,복수화 전환 검토 요청 필히 부탁드립니다. 감사합니다. | AT38: N
A39: Q4592954 | C39: 포스코 | D39: Pneumatic Cylinder | E39: Pneumatic Cylinder | F39: 전아람 | G39: 특정사양품(단수) | H39: ACTIVE | I39: L | J39: KRW | K39: CWC(DA),TC,180Dx45Dx200ST,[CS1TN180-200-CJBD0280/SMC],FOR 1CGL BANDING MACHINE CARRIDGE SHIFTING CYLINDER,OR EQUIVALENT | L39: EA | M39: STANDARD | N39: CS1TN180-200-CJBD0280 | O39: SMC | R39: NONE | X39: FOR 1CGL BANDING MACHINE CARRIDGE SHIFTING CYLINDER | AB39: CS1TN180-200-CJBD0280 도면_20230309101508507.jpg | AE39: https://www.smckorea.co.kr/ | AH39: CS1TN180-200-CJBD0280 도면_20230308172721343.jpg | AJ39: 김응백 | AK39: (포항)압연설비2부 냉연정비2섹션 | AL39: kebe12@posco.co.kr | AM39: 박동방석 | AN39: (포항)압연설비2부 냉연정비2섹션 | AP39: 2023-03-14 09:03:51 | AQ39: 2023 | AR39: 불가피 품목 | AS39: MRO e-Caltalog시스템 경유건으로 대체 Maker 미 발굴건,도금 1CGL Banding Machine Carridge Shifting Cylinder의 핵심 부품으로 기 설치된 Pneumatic Cylinder의 호환성을 위해 특정 사양으로 등록건 확인 후 승인,(특정 사양품감축 관련) 차후 입고시 스케치, 현물 확인을 통한 도면화,일반 사양화,복수화 전환 검토 요청 필히 부탁드립니다. (주)TPC메카트로닉스 기술영업팀 노민영책임(010-9323-4684)과 복수화 재 검토 요청 부탁드립니다.감사합니다. | AT39: N
A40: Q4592850 | C40: 포스코 | D40: Pneumatic Cylinder | E40: Pneumatic Cylinder | F40: 전아람 | G40: 특정사양품(단수) | H40: ACTIVE | I40: L | J40: KRW | K40: CWC(DA),TC,250Dx60Dx1750ST,[CS1TN250-1750-CJBD0272/SMC],FOR 1CGL BANDING FRAME HEAD LIFTING CYLINDER | L40: EA | M40: STANDARD | N40: CS1TN250-1750-CJBD0272 | O40: SMC | R40: NONE | X40: FOR 1CGL BANDING FRAME HEAD LIFTING CYLINDER | AB40: CS1TN250-1750-CJBD0272 도면_20230309101322838.jpg | AE40: https://www.smckorea.co.kr | AH40: CS1TN250-1750-CJBD0272 도면_20230308172501550.jpg | AJ40: 김응백 | AK40: (포항)압연설비2부 냉연정비2섹션 | AL40: kebe12@posco.co.kr | AM40: 박동방석 | AN40: (포항)압연설비2부 냉연정비2섹션 | AP40: 2023-03-13 09:03:11 | AQ40: 2023 | AR40: 차후 재점검 | AS40: MRO e-Caltalog시스템 공급사 소개건으로 대체 Maker 미 발굴건, 기 설치된 Pneumatic Cylinder의 호환성을 위해 특정 사양으로 등록건 확인 후 승인,_x000D_ (특정 사양품감축 관련) 차후 입고시 스케치, 현물 확인을 통한 도면화,일반 사양화,복수화 전환 검토 요청 필히 부탁드립니다. 감사합니다._x000D_ | AT40: N
...

Sheet 실린더 상세사양값. 80
A1: ITEM코드 | B1: 처리상태 | C1: 자재특성구분 | D1: 해당여부 | E1: 물품(Leaf Class)명 | F1: 그룹사명 | G1: 사양/규격 | H1: 개정차수 | I1: 단위 | J1: 조달구분 | K1: 신청자 | L1: 도면번호 | M1: 행번호 | N1: 첨부URL1 | O1: 첨부URL2 | P1: 첨부URL3 | Q1: SPEC_TITLE_1 | R1: SPEC_VALUE_1 | S1: SPEC_TITLE_2 | T1: SPEC_VALUE_2 | U1: SPEC_TITLE_3 | V1: SPEC_VALUE_3 | W1: SPEC_TITLE_4 | X1: SPEC_VALUE_4 | Y1: SPEC_TITLE_5 | Z1: SPEC_VALUE_5 | AA1: SPEC_TITLE_6 | AB1: SPEC_VALUE_6 | AC1: SPEC_TITLE_7 | AD1: SPEC_VALUE_7 | AE1: SPEC_TITLE_8 | AF1: SPEC_VALUE_8 | AG1: SPEC_TITLE_9 | AH1: SPEC_VALUE_9 | AI1: SPEC_TITLE_10 | AJ1: SPEC_VALUE_10 | AK1: SPEC_TITLE_11 | AL1: SPEC_VALUE_11 | AM1: SPEC_TITLE_12 | AN1: SPEC_VALUE_12 | AO1: SPEC_TITLE_13 | AP1: SPEC_VALUE_13 | AQ1: SPEC_TITLE_14 | AR1: SPEC_VALUE_14 | AS1: SPEC_TITLE_15 | AT1: SPEC_VALUE_15 | AU1: SPEC_TITLE_16 | AV1: SPEC_VALUE_16 | AW1: SPEC_TITLE_17 | AX1: SPEC_VALUE_17 | AY1: SPEC_TITLE_18 | AZ1: SPEC_VALUE_18 | BA1: SPEC_TITLE_19 | BB1: SPEC_VALUE_19 | BC1: SPEC_TITLE_20 | BD1: SPEC_VALUE_20 | BE1: SPEC_TITLE_21 | BF1: SPEC_VALUE_21 | BG1: SPEC_TITLE_22 | BH1: SPEC_VALUE_22 | BI1: SPEC_TITLE_23 | BJ1: SPEC_VALUE_23 | BK1: SPEC_TITLE_24 | BL1: SPEC_VALUE_24 | BM1: SPEC_TITLE_25 | BN1: SPEC_VALUE_25 | BO1: SPEC_TITLE_26 | BP1: SPEC_VALUE_26 | BQ1: SPEC_TITLE_27 | BR1: SPEC_VALUE_27 | BS1: SPEC_TITLE_28 | BT1: SPEC_VALUE_28 | BU1: SPEC_TITLE_29 | BV1: SPEC_VALUE_29 | BW1: SPEC_TITLE_30 | BX1: SPEC_VALUE_30 | BY1: SPEC_TITLE_31 | BZ1: SPEC_VALUE_31 | CA1: SPEC_TITLE_32 | CB1: SPEC_VALUE_32 | CC1: SPEC_TITLE_33 | CD1: SPEC_VALUE_33 | CE1: SPEC_TITLE_34 | CF1: SPEC_VALUE_34 | CG1: SPEC_VALUE_34
A2: Q4269320 | B2: ACTIVE | C2: 특정사양품(단수) | D2: Q4269320 | E2: Pneumatic Cylinder | F2: 포스코 | G2: CWC(DA),CA,160Dx40Dx900ST,10kgf/cm2,[CS1CN160-900-CJQD1890/SMC],FOR 2SMP KR IMPELLER SLAG CUTING CYLINDER,OR EQUIVALENT | H2: 1 | I2: SET | J2: L | K2: 하성원 | N2: http://www.smckorea.co.kr/posco/Q1890D_AP.tif | Q2: Used Goods | S2: Green Purchase | T2: NONE | U2: Safety Management | V2: NONE | W2: Posco Patent | Y2: Or Equivalent | Z2: OR EQUIVALENT | AA2: Cylinder Type | AB2: CWC(DA) | AC2: Mounting Type | AD2: CA | AE2: Bore Size | AF2: 160 | AG2: Rod Diameter | AH2: 40 | AI2: Stroke Length | AJ2: 900 | AK2: Pressure Rating | AL2: 10 | AM2: Model-1 | AN2: CS1CN160-900-CJQD1890 | AO2: Maker Name-1 | AP2: SMC | AQ2: Option-1 | AS2: Model-2 | AU2: Maker Name-2 | AV2: NONE | AW2: Option-2 | AY2: Model-3 | BA2: Maker Name-3 | BC2: Option-3 | BE2: Option & Others | BG2: Application | BH2: FOR 2SMP KR IMPELLER SLAG CUTING CYLINDER
A3: Q4507377 | B3: ACTIVE | C3: 특정사양품(단수) | D3: Q4507377 | E3: Pneumatic Cylinder | F3: 포스코 | G3: CWC(DA),FA,50Dx20Dx10ST,10kgf/cm2,[CDQMB50-10-A72/SMC],FOR 2ZRM ROLL CHANGE CAR LIFTER ROLL SHIFT CYLINDER,OR EQUIVALENT | H3: 1 | I3: EA | J3: L | K3: 박용봉 | N3: http://www.smckorea.co.kr/ppis/data/catalog/CQM.pdf | Q3: Used Goods | S3: Green Purchase | T3: NONE | U3: Safety Management | V3: NONE | W3: Posco Patent | Y3: Or Equivalent | Z3: OR EQUIVALENT | AA3: Cylinder Type | AB3: CWC(DA) | AC3: Mounting Type | AD3: FA | AE3: Bore Size | AF3: 50 | AG3: Rod Diameter | AH3: 20 | AI3: Stroke Length | AJ3: 10 | AK3: Pressure Rating | AL3: 10 | AM3: Model-1 | AN3: CDQMB50-10-A72 | AO3: Maker Name-1 | AP3: SMC | AQ3: Option-1 | AS3: Model-2 | AU3: Maker Name-2 | AV3: NONE | AW3: Option-2 | AY3: Model-3 | BA3: Maker Name-3 | BC3: Option-3 | BE3: Option & Others | BG3: Application | BH3: FOR 2ZRM ROLL CHANGE CAR LIFTER ROLL SHIFT CYLINDER
A4: Q4508586 | B4: ACTIVE | C4: 특정사양품(단수) | D4: Q4508586 | E4: Pneumatic Cylinder | F4: 포스코 | G4: CWC(DA),[CDM2E32-200Z-NW-A93L/SMC],4CC MARKING | H4: 1 | I4: SET | J4: L | K4: 김재석 | N4: http://www.smckorea.co.kr/ppis/data/catalog/CM2-Z.pdf | Q4: Used Goods | S4: Green Purchase | T4: NONE | U4: Safety Management | V4: NONE | W4: Posco Patent | Y4: Or Equivalent | AA4: Cylinder Type | AB4: CWC(DA) | AC4: Mounting Type | AD4: OTHERS | AE4: Bore Size | AF4: 9999 | AG4: Rod Diameter | AH4: 9999 | AI4: Stroke Length | AJ4: 9999 | AK4: Pressure Rating | AM4: Model-1 | AN4: CDM2E32-200Z-NW-A93L | AO4: Maker Name-1 | AP4: SMC | AQ4: Option-1 | AS4: Model-2 | AU4: Maker Name-2 | AV4: NONE | AW4: Option-2 | AY4: Model-3 | BA4: Maker Name-3 | BC4: Option-3 | BE4: Option & Others | BG4: Application | BH4: 4CC MARKING
A5: Q4510521 | B5: ACTIVE | C5: 특정사양품(단수) | D5: Q4510521 | E5: Pneumatic Cylinder | F5: 포스코퓨처엠 | G5: CWC(DA),CA,80Dx25Dx100ST,10kgf/cm2,[CDQ2B80-100DMZ-XA18/SMC] | H5: 1 | I5: SET | J5: L | K5: 김 지환 | N5: http://www.smckorea.co.kr/ppis/data/catalog/CQ-Z.pdf | Q5: Used Goods | S5: Green Purchase | T5: NONE | U5: Safety Management | V5: NONE | W5: Posco Patent | Y5: Or Equivalent | AA5: Cylinder Type | AB5: CWC(DA) | AC5: Mounting Type | AD5: CA | AE5: Bore Size | AF5: 80 | AG5: Rod Diameter | AH5: 25 | AI5: Stroke Length | AJ5: 100 | AK5: Pressure Rating | AL5: 10 | AM5: Model-1 | AN5: CDQ2B80-100DMZ-XA18 | AO5: Maker Name-1 | AP5: SMC | AQ5: Option-1 | AS5: Model-2 | AU5: Maker Name-2 | AV5: NONE | AW5: Option-2 | AY5: Model-3 | BA5: Maker Name-3 | BC5: Option-3 | BE5: Option & Others | BG5: Application
